Workbook

Sheet Guida_v3
A1: LexShield | Modello finanziario v3.1
A2: Versione v3.1, 7 ottobre 2026: 13 correzioni sulla v3 del 6 ottobre, elencate in Fonti_Modifiche dalla riga 26. Originali non modificati.
A4: Argomento | B4: Istruzioni
A5: Scopo | B5: Modello gestionale mensile 2027–2031 per due società. La v3 corregge dipendenze, capacità, liquidità e controlli; non valida contratti, mercato o qualifiche giuridiche.
A6: Partenza | B6: Aprire Cruscotto. Scegliere scenario in Ipotesi!C5. Tutti i nove scenari sono ricalcolati dalle stesse ipotesi.
A7: Input da confermare | B7: Compilare le celle gialle di Parametri_v3, verificare Finanziamenti e Piano_SS. Le due quote consulenziali sono intenzionalmente vuote.
A8: Colori | B8: Blu: input; nero: formule; verde: collegamenti diretti. I valori V2_Riferimento sono snapshot storici, non motore.
A9: Crescita SaaS | B9: Clienti nuovi limitati da obiettivo, budget/CAC ritardato, funnel e capacità sviluppatori/supporto. Churn mensile derivato dal tasso annuo. Pricing annuo applicato a tutti i clienti: ipotesi di rinnovo semplificata.
A10: Ricavi servizi | B10: Giornate vendute limitate da capacità. Preparazione formazione esplicita, R&S sottratta dalla capacità tecnica. Nessun contributo gratuito dei soci presunto.
A11: Finanziamenti | B11: Default include fonti pianificate non confermate. Parametri_v3!C6=1 esclude le fonti esterne con status 0; gli apporti iniziali restano input separati. Scenari 6–9 stressano indisponibilità delle fonti.
A12: Cassa e patrimonio | B12: Saldo negativo = deficit non finanziato. I periodi successivi sono condizionati a nuova copertura. Scadenza fido proposta a dicembre 2031, modificabile in Parametri_v3!C63.
A13: IVA e imposte | B13: IVA a 22% e quote imponibili sono ipotesi da validare. Incassi/pagamenti lordi, compensazione IVA e imposte gestionali con acconti storici; nessuna dichiarazione fiscale prodotta. IRAP e rettifiche fiscali restano semplificate.
A14: TFR | B14: Quota del costo all-in già presente, non costo aggiuntivo. Accumulo del fondo e liquidazioni separati: parametrizzazione da sostituire con dati paghe.
A15: Smart&Start | B15: Budget 500 mila allocato a cinque categorie, spese pagate stimate, tetti e date. Contributo escluso sul circolante; quota non rimborsabile proiettata ai SAL nel CE gestionale, da validare contabilmente.
... A23: Novità v3.1 | B23: Leve per scenario su CAC (Ipotesi riga 27), FTE fatturabili e costi fissi (righe 125-126); dividendi bloccati dopo deficit; R&S al netto del supporto clienti; flag fondo perduto (Parametri_v3!C64); scadenza fido 12/2032; organico startup 2029-2031 ridotto.

Sheet Cruscotto
A1: Decisioni e liquidità | scenario selezionato
A2: Non confondere assenza di errori di formula con sostenibilità economica.
A4: Indicatore | B4: Valore (€ ove applicabile) | C4: Lettura
A5: Scenario selezionato | B5: =INDEX(Ipotesi!$C$6:$K$6,1,Ipotesi!$C$5) -> Base | C5: Modificare Ipotesi!C5 da 1 a 9.
A6: Regime finanziamenti | B6: =IF(Parametri_v3!C6=1,"SOLO ESTERNI CONFERMATI","FONTI ESTERNE IPOTIZZATE") -> FONTI ESTERNE IPOTIZZATE | C6: Le erogazioni non sono garanzie di disponibilità.
A7: Ricavi gruppo 2031 | B7: =Gruppo!G9 -> 3651225.3 | C7: Derivati da capacità, budget acquisizione e churn.
A8: EBITDA gruppo 2031 | B8: =Gruppo!G10 -> 446595.61 | C8: Esclusi contributi SS.
A9: Minimo mensile cassa startup | B9: =MIN(Startup!C19:G19) -> -73138.76 | C9: Include utilizzo fido massimo disponibile nello scenario.
A10: Minimo mensile cassa Advisory | B10: =MIN(Advisory!C19:G19) -> -16783.08 | C10: Non compensare automaticamente con cassa startup.
A11: Picco capitale aggiuntivo startup | B11: =MAX(Startup!C20:G20) -> 98138.76 | C11: Incluso buffer proposto; fabbisogno NON finanziato.
A12: Picco capitale aggiuntivo Advisory | B12: =MAX(Advisory!C20:G20) -> 26783.08 | C12: Separato; non sommare i picchi come simultanei senza controllare i mesi.
A13: Patrimonio startup 2031 | B13: =Startup!G37 -> 88867.762 | C13: Pro forma condizionato, con perdite e riserve.
A14: Clienti SaaS 2031 | B14: =Gruppo!G14 -> 228.89967 | C14: Valori attesi, anche frazionari.
A15: Rapporto R&S 2031 | B15: =Requisiti!G9 -> 0.17394745 | C15: Denominatore corretto gestionale; ammissibilità non attestata.
A16: Esito finanziario | B16: =IF(OR(MIN(Startup!C19:G19)<0,MIN(Advisory!C19:G19)<0),"DEFICIT: PIANO NON FINANZIATO","CASSA NON NEGATIVA NELLO SCENARIO") -> DEFICIT: PIANO NON FINANZIATO | C16: L'esito non valida mercato, status o concessioni.
A17: Esito tecnico | B17: =IF(MAX(Controlli!B5:B9)<0.01,"QUADRATURE OK","VERIFICARE QUADRATURE") -> QUADRATURE OK | C17: Controllo contabile automatico, non certificazione.
A18: Primo mese con deficit di cassa | B18: =IFERROR(INDEX(Tesoreria!A5:A64,MATCH(1,Tesoreria!M5:M64,0)),"NESSUNO") -> 46447 | C18: Prima cassa negativa in una delle società; vedere Tesoreria.
A19: Picco gap simultaneo di gruppo | B19: =MAX(Tesoreria!L5:L64) -> 104317.9 | C19: Somma dei fabbisogni nello stesso mese, con buffer separati.
A20: Anno | B20: Ricavi gruppo | C20: EBITDA gruppo | D20: Cassa startup | E20: Cassa Advisory
A21: 2027 | B21: =Gruppo!C9 -> 288276.32 | C21: =Gruppo!C10 -> -171028.84 | D21: =Gruppo!C24 -> 25000 | E21: =Gruppo!C25 -> 26513.727
A22: 2028 | B22: =Gruppo!D9 -> 732688.61 | C22: =Gruppo!D10 -> -263199.15 | D22: =Gruppo!D24 -> 40136.79 | E22: =Gruppo!D25 -> 15038.563
A23: 2029 | B23: =Gruppo!E9 -> 1533406.2 | C23: =Gruppo!E10 -> -350161.38 | D23: =Gruppo!E24 -> 448452.52 | E23: =Gruppo!E25 -> 99567.655
A24: 2030 | B24: =Gruppo!F9 -> 2580413.9 | C24: =Gruppo!F10 -> 52824.185 | D24: =Gruppo!F24 -> 28722.381 | E24: =Gruppo!F25 -> 218002.56
A25: 2031 | B25: =Gruppo!G9 -> 3651225.3 | C25: =Gruppo!G10 -> 446595.61 | D25: =Gruppo!G24 -> 25000 | E25: =Gruppo!G25 -> 341896.8
A27: Minimo cassa startup escluso rimborso finale fido | B27: =MIN(INDEX(Motore_Startup!$BH$5:$BH$544,(Ipotesi!$C$5-1)*60+1):INDEX(Motore_Startup!$BH$5:$BH$544,(Ipotesi!$C$5-1)*60+60))+INDEX(Motore_Startup!$BF$5:$BF$544,(Ipotesi!$C$5-1)*60+60) -> -73138.76 | C27: Utile se la scadenza fido (Parametri_v3!C63) cade nel 2031.

Sheet Gruppo
A1: Gruppo | aggregato gestionale delle due società
A2: Ricavi e partite reciproche eliminati; non è un bilancio consolidato civilistico.
A4: Indicatore | B4: Unità | C4: 2027 | D4: 2028 | E4: 2029 | F4: 2030 | G4: 2031
A5: Ricavi tecnici esterni | B5: € | C5: =SUM(INDEX(Motore_Operativo!$AQ$5:$AQ$544,(Ipotesi!$C$5-1)*60+0*12+1):INDEX(Motore_Operativo!$AQ$5:$AQ$544,((Ipotesi!$C$5-1)*60+0*12+1)+11)) -> 90000 | D5: =SUM(INDEX(Motore_Operativo!$AQ$5:$AQ$544,(Ipotesi!$C$5-1)*60+1*12+1):INDEX(Motore_Operativo!$AQ$5:$AQ$544,((Ipotesi!$C$5-1)*60+1*12+1)+11)) -> 256500 | E5: =SUM(INDEX(Motore_Operativo!$AQ$5:$AQ$544,(Ipotesi!$C$5-1)*60+2*12+1):INDEX(Motore_Operativo!$AQ$5:$AQ$544,((Ipotesi!$C$5-1)*60+2*12+1)+11)) -> 500000 | F5: =SUM(INDEX(Motore_Operativo!$AQ$5:$AQ$544,(Ipotesi!$C$5-1)*60+3*12+1):INDEX(Motore_Operativo!$AQ$5:$AQ$544,((Ipotesi!$C$5-1)*60+3*12+1)+11)) -> 777000 | G5: =SUM(INDEX(Motore_Operativo!$AQ$5:$AQ$544,(Ipotesi!$C$5-1)*60+4*12+1):INDEX(Motore_Operativo!$AQ$5:$AQ$544,((Ipotesi!$C$5-1)*60+4*12+1)+11)) -> 1078000
A6: Ricavi SaaS | B6: € | C6: =SUM(INDEX(Motore_Operativo!$BF$5:$BF$544,(Ipotesi!$C$5-1)*60+0*12+1):INDEX(Motore_Operativo!$BF$5:$BF$544,((Ipotesi!$C$5-1)*60+0*12+1)+11)) -> 3750 | D6: =SUM(INDEX(Motore_Operativo!$BF$5:$BF$544,(Ipotesi!$C$5-1)*60+1*12+1):INDEX(Motore_Operativo!$BF$5:$BF$544,((Ipotesi!$C$5-1)*60+1*12+1)+11)) -> 68413.96 | E6: =SUM(INDEX(Motore_Operativo!$BF$5:$BF$544,(Ipotesi!$C$5-1)*60+2*12+1):INDEX(Motore_Operativo!$BF$5:$BF$544,((Ipotesi!$C$5-1)*60+2*12+1)+11)) -> 307406.25 | F6: =SUM(INDEX(Motore_Operativo!$BF$5:$BF$544,(Ipotesi!$C$5-1)*60+3*12+1):INDEX(Motore_Operativo!$BF$5:$BF$544,((Ipotesi!$C$5-1)*60+3*12+1)+11)) -> 720513.92 | G6: =SUM(INDEX(Motore_Operativo!$BF$5:$BF$544,(Ipotesi!$C$5-1)*60+4*12+1):INDEX(Motore_Operativo!$BF$5:$BF$544,((Ipotesi!$C$5-1)*60+4*12+1)+11)) -> 1181725.3
A7: Ricavi consulenza | B7: € | C7: =SUM(INDEX(Motore_Operativo!$AK$5:$AK$544,(Ipotesi!$C$5-1)*60+0*12+1):INDEX(Motore_Operativo!$AK$5:$AK$544,((Ipotesi!$C$5-1)*60+0*12+1)+11)) -> 145894.74 | D7: =SUM(INDEX(Motore_Operativo!$AK$5:$AK$544,(Ipotesi!$C$5-1)*60+1*12+1):INDEX(Motore_Operativo!$AK$5:$AK$544,((Ipotesi!$C$5-1)*60+1*12+1)+11)) -> 312338.03 | E7: =SUM(INDEX(Motore_Operativo!$AK$5:$AK$544,(Ipotesi!$C$5-1)*60+2*12+1):INDEX(Motore_Operativo!$AK$5:$AK$544,((Ipotesi!$C$5-1)*60+2*12+1)+11)) -> 561000 | F7: =SUM(INDEX(Motore_Operativo!$AK$5:$AK$544,(Ipotesi!$C$5-1)*60+3*12+1):INDEX(Motore_Operativo!$AK$5:$AK$544,((Ipotesi!$C$5-1)*60+3*12+1)+11)) -> 837900 | G7: =SUM(INDEX(Motore_Operativo!$AK$5:$AK$544,(Ipotesi!$C$5-1)*60+4*12+1):INDEX(Motore_Operativo!$AK$5:$AK$544,((Ipotesi!$C$5-1)*60+4*12+1)+11)) -> 1092500
A8: Ricavi formazione | B8: € | C8: =SUM(INDEX(Motore_Operativo!$AL$5:$AL$544,(Ipotesi!$C$5-1)*60+0*12+1):INDEX(Motore_Operativo!$AL$5:$AL$544,((Ipotesi!$C$5-1)*60+0*12+1)+11)) -> 48631.579 | D8: =SUM(INDEX(Motore_Operativo!$AL$5:$AL$544,(Ipotesi!$C$5-1)*60+1*12+1):INDEX(Motore_Operativo!$AL$5:$AL$544,((Ipotesi!$C$5-1)*60+1*12+1)+11)) -> 95436.62 | E8: =SUM(INDEX(Motore_Operativo!$AL$5:$AL$544,(Ipotesi!$C$5-1)*60+2*12+1):INDEX(Motore_Operativo!$AL$5:$AL$544,((Ipotesi!$C$5-1)*60+2*12+1)+11)) -> 165000 | F8: =SUM(INDEX(Motore_Operativo!$AL$5:$AL$544,(Ipotesi!$C$5-1)*60+3*12+1):INDEX(Motore_Operativo!$AL$5:$AL$544,((Ipotesi!$C$5-1)*60+3*12+1)+11)) -> 245000 | G8: =SUM(INDEX(Motore_Operativo!$AL$5:$AL$544,(Ipotesi!$C$5-1)*60+4*12+1):INDEX(Motore_Operativo!$AL$5:$AL$544,((Ipotesi!$C$5-1)*60+4*12+1)+11)) -> 299000
A9: Ricavi esterni di gruppo | B9: € | C9: =SUM(C5:C8) -> 288276.32 | D9: =SUM(D5:D8) -> 732688.61 | E9: =SUM(E5:E8) -> 1533406.2 | F9: =SUM(F5:F8) -> 2580413.9 | G9: =SUM(G5:G8) -> 3651225.3
A10: EBITDA di gruppo senza contributi | B10: € | C10: =Startup!C9+Advisory!C9 -> -171028.84 | D10: =Startup!D9+Advisory!D9 -> -263199.15 | E10: =Startup!E9+Advisory!E9 -> -350161.38 | F10: =Startup!F9+Advisory!F9 -> 52824.185 | G10: =Startup!G9+Advisory!G9 -> 446595.61
A11: Margine EBITDA | B11: % | C11: =IF(C9=0,0,C10/C9) -> -0.59328093 | D11: =IF(D9=0,0,D10/D9) -> -0.35922375 | E11: =IF(E9=0,0,E10/E9) -> -0.22835526 | F11: =IF(F9=0,0,F10/F9) -> 0.020471206 | G11: =IF(G9=0,0,G10/G9) -> 0.1223139
A12: Utile netto aggregato | B12: € | C12: =Startup!C16+Advisory!C16 -> -176453.47 | D12: =Startup!D16+Advisory!D16 -> -246208.03 | E12: =Startup!E16+Advisory!E16 -> -386461.1 | F12: =Startup!F16+Advisory!F16 -> -72172.842 | G12: =Startup!G16+Advisory!G16 -> 278317.87
A14: Clienti SaaS finali | B14: clienti | C14: =INDEX(Motore_Operativo!$BD$5:$BD$544,((Ipotesi!$C$5-1)*60+0*12+1)+11) -> 5 | D14: =INDEX(Motore_Operativo!$BD$5:$BD$544,((Ipotesi!$C$5-1)*60+1*12+1)+11) -> 32.63937 | E14: =INDEX(Motore_Operativo!$BD$5:$BD$544,((Ipotesi!$C$5-1)*60+2*12+1)+11) -> 88.253797 | F14: =INDEX(Motore_Operativo!$BD$5:$BD$544,((Ipotesi!$C$5-1)*60+3*12+1)+11) -> 154.906 | G14: =INDEX(Motore_Operativo!$BD$5:$BD$544,((Ipotesi!$C$5-1)*60+4*12+1)+11) -> 228.89967
A15: ARR SaaS | B15: € | C15: =INDEX(Motore_Operativo!$BG$5:$BG$544,((Ipotesi!$C$5-1)*60+0*12+1)+11) -> 10000 | D15: =INDEX(Motore_Operativo!$BG$5:$BG$544,((Ipotesi!$C$5-1)*60+1*12+1)+11) -> 130557.48 | E15: =INDEX(Motore_Operativo!$BG$5:$BG$544,((Ipotesi!$C$5-1)*60+2*12+1)+11) -> 485395.88 | F15: =INDEX(Motore_Operativo!$BG$5:$BG$544,((Ipotesi!$C$5-1)*60+3*12+1)+11) -> 929436.02 | G15: =INDEX(Motore_Operativo!$BG$5:$BG$544,((Ipotesi!$C$5-1)*60+4*12+1)+11) -> 1419177.9
A16: Nuovi clienti nell'anno | B16: clienti | C16: =SUM(INDEX(Motore_Operativo!$BC$5:$BC$544,(Ipotesi!$C$5-1)*60+0*12+1):INDEX(Motore_Operativo!$BC$5:$BC$544,((Ipotesi!$C$5-1)*60+0*12+1)+11)) -> 5 | D16: =SUM(INDEX(Motore_Operativo!$BC$5:$BC$544,(Ipotesi!$C$5-1)*60+1*12+1):INDEX(Motore_Operativo!$BC$5:$BC$544,((Ipotesi!$C$5-1)*60+1*12+1)+11)) -> 29.312708 | E16: =SUM(INDEX(Motore_Operativo!$BC$5:$BC$544,(Ipotesi!$C$5-1)*60+2*12+1):INDEX(Motore_Operativo!$BC$5:$BC$544,((Ipotesi!$C$5-1)*60+2*12+1)+11)) -> 61.234385 | F16: =SUM(INDEX(Motore_Operativo!$BC$5:$BC$544,(Ipotesi!$C$5-1)*60+3*12+1):INDEX(Motore_Operativo!$BC$5:$BC$544,((Ipotesi!$C$5-1)*60+3*12+1)+11)) -> 78.957788 | G16: =SUM(INDEX(Motore_Operativo!$BC$5:$BC$544,(Ipotesi!$C$5-1)*60+4*12+1):INDEX(Motore_Operativo!$BC$5:$BC$544,((Ipotesi!$C$5-1)*60+4*12+1)+11)) -> 93.664154
A17: Clienti persi nell'anno | B17: clienti | C17: =SUM(INDEX(Motore_Operativo!$AW$5:$AW$544,(Ipotesi!$C$5-1)*60+0*12+1):INDEX(Motore_Operativo!$AW$5:$AW$544,((Ipotesi!$C$5-1)*60+0*12+1)+11)) -> 0 | D17: =SUM(INDEX(Motore_Operativo!$AW$5:$AW$544,(Ipotesi!$C$5-1)*60+1*12+1):INDEX(Motore_Operativo!$AW$5:$AW$544,((Ipotesi!$C$5-1)*60+1*12+1)+11)) -> 1.6733384 | E17: =SUM(INDEX(Motore_Operativo!$AW$5:$AW$544,(Ipotesi!$C$5-1)*60+2*12+1):INDEX(Motore_Operativo!$AW$5:$AW$544,((Ipotesi!$C$5-1)*60+2*12+1)+11)) -> 5.6199583 | F17: =SUM(INDEX(Motore_Operativo!$AW$5:$AW$544,(Ipotesi!$C$5-1)*60+3*12+1):INDEX(Motore_Operativo!$AW$5:$AW$544,((Ipotesi!$C$5-1)*60+3*12+1)+11)) -> 12.305581 | G17: =SUM(INDEX(Motore_Operativo!$AW$5:$AW$544,(Ipotesi!$C$5-1)*60+4*12+1):INDEX(Motore_Operativo!$AW$5:$AW$544,((Ipotesi!$C$5-1)*60+4*12+1)+11)) -> 19.67049
A18: Budget acquisizione SaaS | B18: € | C18: =SUM(INDEX(Motore_Operativo!$AT$5:$AT$544,(Ipotesi!$C$5-1)*60+0*12+1):INDEX(Motore_Operativo!$AT$5:$AT$544,((Ipotesi!$C$5-1)*60+0*12+1)+11)) -> 40750 | D18: =SUM(INDEX(Motore_Operativo!$AT$5:$AT$544,(Ipotesi!$C$5-1)*60+1*12+1):INDEX(Motore_Operativo!$AT$5:$AT$544,((Ipotesi!$C$5-1)*60+1*12+1)+11)) -> 103667.5 | E18: =SUM(INDEX(Motore_Operativo!$AT$5:$AT$544,(Ipotesi!$C$5-1)*60+2*12+1):INDEX(Motore_Operativo!$AT$5:$AT$544,((Ipotesi!$C$5-1)*60+2*12+1)+11)) -> 373673.4 | F18: =SUM(INDEX(Motore_Operativo!$AT$5:$AT$544,(Ipotesi!$C$5-1)*60+3*12+1):INDEX(Motore_Operativo!$AT$5:$AT$544,((Ipotesi!$C$5-1)*60+3*12+1)+11)) -> 507104.5 | G18: =SUM(INDEX(Motore_Operativo!$AT$5:$AT$544,(Ipotesi!$C$5-1)*60+4*12+1):INDEX(Motore_Operativo!$AT$5:$AT$544,((Ipotesi!$C$5-1)*60+4*12+1)+11)) -> 642721.17
A19: CAC corrente (budget anno / nuovi anno; ciclo da considerare) | B19: € | C19: =IF(C16=0,0,C18/C16) -> 8150 | D19: =IF(D16=0,0,D18/D16) -> 3536.606 | E19: =IF(E16=0,0,E18/E16) -> 6102.3459 | F19: =IF(F16=0,0,F18/F16) -> 6422.4761 | G19: =IF(G16=0,0,G18/G16) -> 6861.9759
A20: Margine lordo SaaS da costi | B20: % | C20: =IF(C6=0,0,1-SUM(INDEX(Motore_Operativo!$CL$5:$CL$544,(Ipotesi!$C$5-1)*60+0*12+1):INDEX(Motore_Operativo!$CL$5:$CL$544,((Ipotesi!$C$5-1)*60+0*12+1)+11))/C6) -> -4.88 | D20: =IF(D6=0,0,1-SUM(INDEX(Motore_Operativo!$CL$5:$CL$544,(Ipotesi!$C$5-1)*60+1*12+1):INDEX(Motore_Operativo!$CL$5:$CL$544,((Ipotesi!$C$5-1)*60+1*12+1)+11))/D6) -> 0.39587452 | E20: =IF(E6=0,0,1-SUM(INDEX(Motore_Operativo!$CL$5:$CL$544,(Ipotesi!$C$5-1)*60+2*12+1):INDEX(Motore_Operativo!$CL$5:$CL$544,((Ipotesi!$C$5-1)*60+2*12+1)+11))/E6) -> 0.68484343 | F20: =IF(F6=0,0,1-SUM(INDEX(Motore_Operativo!$CL$5:$CL$544,(Ipotesi!$C$5-1)*60+3*12+1):INDEX(Motore_Operativo!$CL$5:$CL$544,((Ipotesi!$C$5-1)*60+3*12+1)+11))/F6) -> 0.79681144 | G20: =IF(G6=0,0,1-SUM(INDEX(Motore_Operativo!$CL$5:$CL$544,(Ipotesi!$C$5-1)*60+4*12+1):INDEX(Motore_Operativo!$CL$5:$CL$544,((Ipotesi!$C$5-1)*60+4*12+1)+11))/G6) -> 0.83015999
A21: Obiettivo margine lordo SaaS | B21: % | C21: =Ipotesi!$C$36 -> 0.8 | D21: =Ipotesi!$C$36 -> 0.8 | E21: =Ipotesi!$C$36 -> 0.8 | F21: =Ipotesi!$C$36 -> 0.8 | G21: =Ipotesi!$C$36 -> 0.8
A23: Organico medio gruppo (FTE) | B23: FTE | C23: =AVERAGE(INDEX(Motore_Operativo!$M$5:$M$544,(Ipotesi!$C$5-1)*60+0*12+1):INDEX(Motore_Operativo!$M$5:$M$544,((Ipotesi!$C$5-1)*60+0*12+1)+11))+AVERAGE(INDEX(Motore_Operativo!$N$5:$N$544,(Ipotesi!$C$5-1)*60+0*12+1):INDEX(Motore_Operativo!$N$5:$N$544,((Ipotesi!$C$5-1)*60+0*12+1)+11))+AVERAGE(INDEX(Motore_Operativo!$O$5:$O$544,(Ipotesi!$C$5-1)*60+0*12+1):INDEX(Motore_Operativo!$O$5:$O$544,((Ipotesi!$C$5-1)*60+0*12+1)+11))+AVERAGE(INDEX(Motore_Operativo!$P$5:$P$544,(Ipotesi!$C$5-1)*60+0*12+1):INDEX(Motore_Operativo!$P$5:$P$544,((Ipotesi!$C$5-1)*60+0*12+1)+11))+AVERAGE(INDEX(Motore_Operativo!$Q$5:$Q$544,(Ipotesi!$C$5-1)*60+0*12+1):INDEX(Motore_Operativo!$Q$5:$Q$544,((Ipotesi!$C$5-1)*60+0*12+1)+11))+AVERAGE(INDEX(Motore_Operativo!$R$5:$R$544,(Ipotesi!$C$5-1)*60+0*12+1):INDEX(Motore_Operativo!$R$5:$R$544,((Ipotesi!$C$5-1)*60+0*12+1)+11))+AVERAGE(INDEX(Motore_Operativo!$S$5:$S$544,(Ipotesi!$C$5-1)*60+0*12+1):INDEX(Motore_Operativo!$S$5:$S$544,((Ipotesi!$C$5-1)*60+0*12+1)+11))+AVERAGE(INDEX(Motore_Operativo!$T$5:$T$544,(Ipotesi!$C$5-1)*60+0*12+1):INDEX(Motore_Operativo!$T$5:$T$544,((Ipotesi!$C$5-1)*60+0*12+1)+11))+AVERAGE(INDEX(Motore_Operativo!$U$5:$U$544,(Ipotesi!$C$5-1)*60+0*12+1):INDEX(Motore_Operativo!$U$5:$U$544,((Ipotesi!$C$5-1)*60+0*12+1)+11)) -> 5.75 | D23: =AVERAGE(INDEX(Motore_Operativo!$M$5:$M$544,(Ipotesi!$C$5-1)*60+1*12+1):INDEX(Motore_Operativo!$M$5:$M$544,((Ipotesi!$C$5-1)*60+1*12+1)+11))+AVERAGE(INDEX(Motore_Operativo!$N$5:$N$544,(Ipotesi!$C$5-1)*60+1*12+1):INDEX(Motore_Operativo!$N$5:$N$544,((Ipotesi!$C$5-1)*60+1*12+1)+11))+AVERAGE(INDEX(Motore_Operativo!$O$5:$O$544,(Ipotesi!$C$5-1)*60+1*12+1):INDEX(Motore_Operativo!$O$5:$O$544,((Ipotesi!$C$5-1)*60+1*12+1)+11))+AVERAGE(INDEX(Motore_Operativo!$P$5:$P$544,(Ipotesi!$C$5-1)*60+1*12+1):INDEX(Motore_Operativo!$P$5:$P$544,((Ipotesi!$C$5-1)*60+1*12+1)+11))+AVERAGE(INDEX(Motore_Operativo!$Q$5:$Q$544,(Ipotesi!$C$5-1)*60+1*12+1):INDEX(Motore_Operativo!$Q$5:$Q$544,((Ipotesi!$C$5-1)*60+1*12+1)+11))+AVERAGE(INDEX(Motore_Operativo!$R$5:$R$544,(Ipotesi!$C$5-1)*60+1*12+1):INDEX(Motore_Operativo!$R$5:$R$544,((Ipotesi!$C$5-1)*60+1*12+1)+11))+AVERAGE(INDEX(Motore_Operativo!$S$5:$S$544,(Ipotesi!$C$5-1)*60+1*12+1):INDEX(Motore_Operativo!$S$5:$S$544,((Ipotesi!$C$5-1)*60+1*12+1)+11))+AVERAGE(INDEX(Motore_Operativo!$T$5:$T$544,(Ipotesi!$C$5-1)*60+1*12+1):INDEX(Motore_Operativo!$T$5:$T$544,((Ipotesi!$C$5-1)*60+1*12+1)+11))+AVERAGE(INDEX(Motore_Operativo!$U$5:$U$544,(Ipotesi!$C$5-1)*60+1*12+1):INDEX(Motore_Operativo!$U$5:$U$544,((Ipotesi!$C$5-1)*60+1*12+1)+11)) -> 13 | E23: =AVERAGE(INDEX(Motore_Operativo!$M$5:$M$544,(Ipotesi!$C$5-1)*60+2*12+1):INDEX(Motore_Operativo!$M$5:$M$544,((Ipotesi!$C$5-1)*60+2*12+1)+11))+AVERAGE(INDEX(Motore_Operativo!$N$5:$N$544,(Ipotesi!$C$5-1)*60+2*12+1):INDEX(Motore_Operativo!$N$5:$N$544,((Ipotesi!$C$5-1)*60+2*12+1)+11))+AVERAGE(INDEX(Motore_Operativo!$O$5:$O$544,(Ipotesi!$C$5-1)*60+2*12+1):INDEX(Motore_Operativo!$O$5:$O$544,((Ipotesi!$C$5-1)*60+2*12+1)+11))+AVERAGE(INDEX(Motore_Operativo!$P$5:$P$544,(Ipotesi!$C$5-1)*60+2*12+1):INDEX(Motore_Operativo!$P$5:$P$544,((Ipotesi!$C$5-1)*60+2*12+1)+11))+AVERAGE(INDEX(Motore_Operativo!$Q$5:$Q$544,(Ipotesi!$C$5-1)*60+2*12+1):INDEX(Motore_Operativo!$Q$5:$Q$544,((Ipotesi!$C$5-1)*60+2*12+1)+11))+AVERAGE(INDEX(Motore_Operativo!$R$5:$R$544,(Ipotesi!$C$5-1)*60+2*12+1):INDEX(Motore_Operativo!$R$5:$R$544,((Ipotesi!$C$5-1)*60+2*12+1)+11))+AVERAGE(INDEX(Motore_Operativo!$S$5:$S$544,(Ipotesi!$C$5-1)*60+2*12+1):INDEX(Motore_Operativo!$S$5:$S$544,((Ipotesi!$C$5-1)*60+2*12+1)+11))+AVERAGE(INDEX(Motore_Operativo!$T$5:$T$544,(Ipotesi!$C$5-1)*60+2*12+1):INDEX(Motore_Operativo!$T$5:$T$544,((Ipotesi!$C$5-1)*60+2*12+1)+11))+AVERAGE(INDEX(Motore_Operativo!$U$5:$U$544,(Ipotesi!$C$5-1)*60+2*12+1):INDEX(Motore_Operativo!$U$5:$U$544,((Ipotesi!$C$5-1)*60+2*12+1)+11)) -> 23 | F23: =AVERAGE(INDEX(Motore_Operativo!$M$5:$M$544,(Ipotesi!$C$5-1)*60+3*12+1):INDEX(Motore_Operativo!$M$5:$M$544,((Ipotesi!$C$5-1)*60+3*12+1)+11))+AVERAGE(INDEX(Motore_Operativo!$N$5:$N$544,(Ipotesi!$C$5-1)*60+3*12+1):INDEX(Motore_Operativo!$N$5:$N$544,((Ipotesi!$C$5-1)*60+3*12+1)+11))+AVERAGE(INDEX(Motore_Operativo!$O$5:$O$544,(Ipotesi!$C$5-1)*60+3*12+1):INDEX(Motore_Operativo!$O$5:$O$544,((Ipotesi!$C$5-1)*60+3*12+1)+11))+AVERAGE(INDEX(Motore_Operativo!$P$5:$P$544,(Ipotesi!$C$5-1)*60+3*12+1):INDEX(Motore_Operativo!$P$5:$P$544,((Ipotesi!$C$5-1)*60+3*12+1)+11))+AVERAGE(INDEX(Motore_Operativo!$Q$5:$Q$544,(Ipotesi!$C$5-1)*60+3*12+1):INDEX(Motore_Operativo!$Q$5:$Q$544,((Ipotesi!$C$5-1)*60+3*12+1)+11))+AVERAGE(INDEX(Motore_Operativo!$R$5:$R$544,(Ipotesi!$C$5-1)*60+3*12+1):INDEX(Motore_Operativo!$R$5:$R$544,((Ipotesi!$C$5-1)*60+3*12+1)+11))+AVERAGE(INDEX(Motore_Operativo!$S$5:$S$544,(Ipotesi!$C$5-1)*60+3*12+1):INDEX(Motore_Operativo!$S$5:$S$544,((Ipotesi!$C$5-1)*60+3*12+1)+11))+AVERAGE(INDEX(Motore_Operativo!$T$5:$T$544,(Ipotesi!$C$5-1)*60+3*12+1):INDEX(Motore_Operativo!$T$5:$T$544,((Ipotesi!$C$5-1)*60+3*12+1)+11))+AVERAGE(INDEX(Motore_Operativo!$U$5:$U$544,(Ipotesi!$C$5-1)*60+3*12+1):INDEX(Motore_Operativo!$U$5:$U$544,((Ipotesi!$C$5-1)*60+3*12+1)+11)) -> 29.5 | G23: =AVERAGE(INDEX(Motore_Operativo!$M$5:$M$544,(Ipotesi!$C$5-1)*60+4*12+1):INDEX(Motore_Operativo!$M$5:$M$544,((Ipotesi!$C$5-1)*60+4*12+1)+11))+AVERAGE(INDEX(Motore_Operativo!$N$5:$N$544,(Ipotesi!$C$5-1)*60+4*12+1):INDEX(Motore_Operativo!$N$5:$N$544,((Ipotesi!$C$5-1)*60+4*12+1)+11))+AVERAGE(INDEX(Motore_Operativo!$O$5:$O$544,(Ipotesi!$C$5-1)*60+4*12+1):INDEX(Motore_Operativo!$O$5:$O$544,((Ipotesi!$C$5-1)*60+4*12+1)+11))+AVERAGE(INDEX(Motore_Operativo!$P$5:$P$544,(Ipotesi!$C$5-1)*60+4*12+1):INDEX(Motore_Operativo!$P$5:$P$544,((Ipotesi!$C$5-1)*60+4*12+1)+11))+AVERAGE(INDEX(Motore_Operativo!$Q$5:$Q$544,(Ipotesi!$C$5-1)*60+4*12+1):INDEX(Motore_Operativo!$Q$5:$Q$544,((Ipotesi!$C$5-1)*60+4*12+1)+11))+AVERAGE(INDEX(Motore_Operativo!$R$5:$R$544,(Ipotesi!$C$5-1)*60+4*12+1):INDEX(Motore_Operativo!$R$5:$R$544,((Ipotesi!$C$5-1)*60+4*12+1)+11))+AVERAGE(INDEX(Motore_Operativo!$S$5:$S$544,(Ipotesi!$C$5-1)*60+4*12+1):INDEX(Motore_Operativo!$S$5:$S$544,((Ipotesi!$C$5-1)*60+4*12+1)+11))+AVERAGE(INDEX(Motore_Operativo!$T$5:$T$544,(Ipotesi!$C$5-1)*60+4*12+1):INDEX(Motore_Operativo!$T$5:$T$544,((Ipotesi!$C$5-1)*60+4*12+1)+11))+AVERAGE(INDEX(Motore_Operativo!$U$5:$U$544,(Ipotesi!$C$5-1)*60+4*12+1):INDEX(Motore_Operativo!$U$5:$U$544,((Ipotesi!$C$5-1)*60+4*12+1)+11)) -> 36.5
A24: Cassa S a fine anno | B24: € | C24: =Startup!C18 -> 25000 | D24: =Startup!D18 -> 40136.79 | E24: =Startup!E18 -> 448452.52 | F24: =Startup!F18 -> 28722.381 | G24: =Startup!G18 -> 25000
A25: Cassa A a fine anno | B25: € | C25: =Advisory!C18 -> 26513.727 | D25: =Advisory!D18 -> 15038.563 | E25: =Advisory!E18 -> 99567.655 | F25: =Advisory!F18 -> 218002.56 | G25: =Advisory!G18 -> 341896.8
A26: Cassa totale a fine anno | B26: € | C26: =C24+C25 -> 51513.727 | D26: =D24+D25 -> 55175.353 | E26: =E24+E25 -> 548020.18 | F26: =F24+F25 -> 246724.94 | G26: =G24+G25 -> 366896.8
A27: Cassa minima startup | B27: € | C27: =Startup!C19 -> 25000 | D27: =Startup!D19 -> -73138.76 | E27: =Startup!E19 -> -73078.563 | F27: =Startup!F19 -> 28722.381 | G27: =Startup!G19 -> 25000
A28: Cassa minima Advisory | B28: € | C28: =Advisory!C19 -> -10462.852 | D28: =Advisory!D19 -> -9688.9021 | E28: =Advisory!E19 -> -16783.08 | F28: =Advisory!F19 -> 73892.896 | G28: =Advisory!G19 -> 169280.37
A29: Fabbisogno massimo startup con buffer | B29: € | C29: =Startup!C20 -> 0 | D29: =Startup!D20 -> 98138.76 | E29: =Startup!E20 -> 98078.563 | F29: =Startup!F20 -> 0 | G29: =Startup!G20 -> 0
A30: Fabbisogno massimo Advisory con buffer | B30: € | C30: =Advisory!C20 -> 20462.852 | D30: =Advisory!D20 -> 19688.902 | E30: =Advisory!E20 -> 26783.08 | F30: =Advisory!F20 -> 0 | G30: =Advisory!G20 -> 0
A32: Patrimonio netto aggregato | B32: € | C32: =Startup!C37+Advisory!C37 -> -26453.47 | D32: =Startup!D37+Advisory!D37 -> 27338.496 | E32: =Startup!E37+Advisory!E37 -> 540877.4 | F32: =Startup!F37+Advisory!F37 -> 444095.67 | G32: =Startup!G37+Advisory!G37 -> 674360.92
A33: Debito finanziario totale | B33: € | C33: =Startup!C21+Startup!C24 -> 122180.44 | D33: =Startup!D21+Startup!D24 -> 176155.05 | E33: =Startup!E21+Startup!E24 -> 265393 | F33: =Startup!F21+Startup!F24 -> 238853.7 | G33: =Startup!G21+Startup!G24 -> 324193.4
A34: Dividendi netti trattenuti dai soci | B34: € | C34: =Advisory!C27*(1-Ipotesi!$C$95)*(1-Ipotesi!$C$96) -> 0 | D34: =Advisory!D27*(1-Ipotesi!$C$95)*(1-Ipotesi!$C$96) -> 0 | E34: =Advisory!E27*(1-Ipotesi!$C$95)*(1-Ipotesi!$C$96) -> 0 | F34: =Advisory!F27*(1-Ipotesi!$C$95)*(1-Ipotesi!$C$96) -> 8926.7541 | G34: =Advisory!G27*(1-Ipotesi!$C$95)*(1-Ipotesi!$C$96) -> 17430.848
A35: Imposta dividendi pagata dai soci | B35: € | C35: =Advisory!C27*Ipotesi!$C$95 -> 0 | D35: =Advisory!D27*Ipotesi!$C$95 -> 0 | E35: =Advisory!E27*Ipotesi!$C$95 -> 0 | F35: =Advisory!F27*Ipotesi!$C$95 -> 15682.136 | G35: =Advisory!G27*Ipotesi!$C$95 -> 30621.761
A36: Scarto saldi IC | B36: € | C36: =Startup!C31-Advisory!C31 -> 0 | D36: =Startup!D31-Advisory!D31 -> 0 | E36: =Startup!E31-Advisory!E31 -> 0 | F36: =Startup!F31-Advisory!F31 -> 0 | G36: =Startup!G31-Advisory!G31 -> 0
A37: Ricavi SaaS obiettivo V2 (solo confronto) | B37: € | C37: =V2_Riferimento!C6 -> 5000 | D37: =V2_Riferimento!D6 -> 80000 | E37: =V2_Riferimento!E6 -> 453750 | F37: =V2_Riferimento!F6 -> 1320000 | G37: =V2_Riferimento!G6 -> 2697000

Sheet Startup
A1: Startup | riepilogo annuale selezionato
A2: Conto economico gestionale, posizione patrimoniale e picco del fabbisogno mensile.
A4: Indicatore | B4: Unità | C4: 2027 | D4: 2028 | E4: 2029 | F4: 2030 | G4: 2031
A5: Ricavi esterni | B5: € | C5: =SUM(INDEX(Motore_Startup!$F$5:$F$544,(Ipotesi!$C$5-1)*60+0*12+1):INDEX(Motore_Startup!$F$5:$F$544,((Ipotesi!$C$5-1)*60+0*12+1)+11)) -> 93750 | D5: =SUM(INDEX(Motore_Startup!$F$5:$F$544,(Ipotesi!$C$5-1)*60+1*12+1):INDEX(Motore_Startup!$F$5:$F$544,((Ipotesi!$C$5-1)*60+1*12+1)+11)) -> 324913.96 | E5: =SUM(INDEX(Motore_Startup!$F$5:$F$544,(Ipotesi!$C$5-1)*60+2*12+1):INDEX(Motore_Startup!$F$5:$F$544,((Ipotesi!$C$5-1)*60+2*12+1)+11)) -> 807406.25 | F5: =SUM(INDEX(Motore_Startup!$F$5:$F$544,(Ipotesi!$C$5-1)*60+3*12+1):INDEX(Motore_Startup!$F$5:$F$544,((Ipotesi!$C$5-1)*60+3*12+1)+11)) -> 1497513.9 | G5: =SUM(INDEX(Motore_Startup!$F$5:$F$544,(Ipotesi!$C$5-1)*60+4*12+1):INDEX(Motore_Startup!$F$5:$F$544,((Ipotesi!$C$5-1)*60+4*12+1)+11)) -> 2259725.3
A6: Canone infragruppo (ricavo S / costo A) | B6: € | C6: =SUM(INDEX(Motore_Startup!$G$5:$G$544,(Ipotesi!$C$5-1)*60+0*12+1):INDEX(Motore_Startup!$G$5:$G$544,((Ipotesi!$C$5-1)*60+0*12+1)+11)) -> 19452.632 | D6: =SUM(INDEX(Motore_Startup!$G$5:$G$544,(Ipotesi!$C$5-1)*60+1*12+1):INDEX(Motore_Startup!$G$5:$G$544,((Ipotesi!$C$5-1)*60+1*12+1)+11)) -> 40777.465 | E6: =SUM(INDEX(Motore_Startup!$G$5:$G$544,(Ipotesi!$C$5-1)*60+2*12+1):INDEX(Motore_Startup!$G$5:$G$544,((Ipotesi!$C$5-1)*60+2*12+1)+11)) -> 72600 | F6: =SUM(INDEX(Motore_Startup!$G$5:$G$544,(Ipotesi!$C$5-1)*60+3*12+1):INDEX(Motore_Startup!$G$5:$G$544,((Ipotesi!$C$5-1)*60+3*12+1)+11)) -> 108290 | G6: =SUM(INDEX(Motore_Startup!$G$5:$G$544,(Ipotesi!$C$5-1)*60+4*12+1):INDEX(Motore_Startup!$G$5:$G$544,((Ipotesi!$C$5-1)*60+4*12+1)+11)) -> 139150
A7: Ricavi conto economico | B7: € | C7: =SUM(INDEX(Motore_Startup!$H$5:$H$544,(Ipotesi!$C$5-1)*60+0*12+1):INDEX(Motore_Startup!$H$5:$H$544,((Ipotesi!$C$5-1)*60+0*12+1)+11)) -> 113202.63 | D7: =SUM(INDEX(Motore_Startup!$H$5:$H$544,(Ipotesi!$C$5-1)*60+1*12+1):INDEX(Motore_Startup!$H$5:$H$544,((Ipotesi!$C$5-1)*60+1*12+1)+11)) -> 365691.43 | E7: =SUM(INDEX(Motore_Startup!$H$5:$H$544,(Ipotesi!$C$5-1)*60+2*12+1):INDEX(Motore_Startup!$H$5:$H$544,((Ipotesi!$C$5-1)*60+2*12+1)+11)) -> 880006.25 | F7: =SUM(INDEX(Motore_Startup!$H$5:$H$544,(Ipotesi!$C$5-1)*60+3*12+1):INDEX(Motore_Startup!$H$5:$H$544,((Ipotesi!$C$5-1)*60+3*12+1)+11)) -> 1605803.9 | G7: =SUM(INDEX(Motore_Startup!$H$5:$H$544,(Ipotesi!$C$5-1)*60+4*12+1):INDEX(Motore_Startup!$H$5:$H$544,((Ipotesi!$C$5-1)*60+4*12+1)+11)) -> 2398875.3
A8: Costi operativi | B8: € | C8: =SUM(INDEX(Motore_Startup!$I$5:$I$544,(Ipotesi!$C$5-1)*60+0*12+1):INDEX(Motore_Startup!$I$5:$I$544,((Ipotesi!$C$5-1)*60+0*12+1)+11)) -> 333383.58 | D8: =SUM(INDEX(Motore_Startup!$I$5:$I$544,(Ipotesi!$C$5-1)*60+1*12+1):INDEX(Motore_Startup!$I$5:$I$544,((Ipotesi!$C$5-1)*60+1*12+1)+11)) -> 690041.28 | E8: =SUM(INDEX(Motore_Startup!$I$5:$I$544,(Ipotesi!$C$5-1)*60+2*12+1):INDEX(Motore_Startup!$I$5:$I$544,((Ipotesi!$C$5-1)*60+2*12+1)+11)) -> 1401048.9 | F8: =SUM(INDEX(Motore_Startup!$I$5:$I$544,(Ipotesi!$C$5-1)*60+3*12+1):INDEX(Motore_Startup!$I$5:$I$544,((Ipotesi!$C$5-1)*60+3*12+1)+11)) -> 1884917.7 | G8: =SUM(INDEX(Motore_Startup!$I$5:$I$544,(Ipotesi!$C$5-1)*60+4*12+1):INDEX(Motore_Startup!$I$5:$I$544,((Ipotesi!$C$5-1)*60+4*12+1)+11)) -> 2388274
A9: EBITDA senza contributi | B9: € | C9: =SUM(INDEX(Motore_Startup!$J$5:$J$544,(Ipotesi!$C$5-1)*60+0*12+1):INDEX(Motore_Startup!$J$5:$J$544,((Ipotesi!$C$5-1)*60+0*12+1)+11)) -> -220180.95 | D9: =SUM(INDEX(Motore_Startup!$J$5:$J$544,(Ipotesi!$C$5-1)*60+1*12+1):INDEX(Motore_Startup!$J$5:$J$544,((Ipotesi!$C$5-1)*60+1*12+1)+11)) -> -324349.85 | E9: =SUM(INDEX(Motore_Startup!$J$5:$J$544,(Ipotesi!$C$5-1)*60+2*12+1):INDEX(Motore_Startup!$J$5:$J$544,((Ipotesi!$C$5-1)*60+2*12+1)+11)) -> -521042.63 | F9: =SUM(INDEX(Motore_Startup!$J$5:$J$544,(Ipotesi!$C$5-1)*60+3*12+1):INDEX(Motore_Startup!$J$5:$J$544,((Ipotesi!$C$5-1)*60+3*12+1)+11)) -> -279113.73 | G9: =SUM(INDEX(Motore_Startup!$J$5:$J$544,(Ipotesi!$C$5-1)*60+4*12+1):INDEX(Motore_Startup!$J$5:$J$544,((Ipotesi!$C$5-1)*60+4*12+1)+11)) -> 10601.279
A10: Ammortamenti | B10: € | C10: =SUM(INDEX(Motore_Startup!$L$5:$L$544,(Ipotesi!$C$5-1)*60+0*12+1):INDEX(Motore_Startup!$L$5:$L$544,((Ipotesi!$C$5-1)*60+0*12+1)+11)) -> 3611.1111 | D10: =SUM(INDEX(Motore_Startup!$L$5:$L$544,(Ipotesi!$C$5-1)*60+1*12+1):INDEX(Motore_Startup!$L$5:$L$544,((Ipotesi!$C$5-1)*60+1*12+1)+11)) -> 11180.556 | E10: =SUM(INDEX(Motore_Startup!$L$5:$L$544,(Ipotesi!$C$5-1)*60+2*12+1):INDEX(Motore_Startup!$L$5:$L$544,((Ipotesi!$C$5-1)*60+2*12+1)+11)) -> 20416.667 | F10: =SUM(INDEX(Motore_Startup!$L$5:$L$544,(Ipotesi!$C$5-1)*60+3*12+1):INDEX(Motore_Startup!$L$5:$L$544,((Ipotesi!$C$5-1)*60+3*12+1)+11)) -> 28611.111 | G10: =SUM(INDEX(Motore_Startup!$L$5:$L$544,(Ipotesi!$C$5-1)*60+4*12+1):INDEX(Motore_Startup!$L$5:$L$544,((Ipotesi!$C$5-1)*60+4*12+1)+11)) -> 36180.556
A11: EBIT | B11: € | C11: =SUM(INDEX(Motore_Startup!$M$5:$M$544,(Ipotesi!$C$5-1)*60+0*12+1):INDEX(Motore_Startup!$M$5:$M$544,((Ipotesi!$C$5-1)*60+0*12+1)+11)) -> -223792.06 | D11: =SUM(INDEX(Motore_Startup!$M$5:$M$544,(Ipotesi!$C$5-1)*60+1*12+1):INDEX(Motore_Startup!$M$5:$M$544,((Ipotesi!$C$5-1)*60+1*12+1)+11)) -> -335530.41 | E11: =SUM(INDEX(Motore_Startup!$M$5:$M$544,(Ipotesi!$C$5-1)*60+2*12+1):INDEX(Motore_Startup!$M$5:$M$544,((Ipotesi!$C$5-1)*60+2*12+1)+11)) -> -541459.29 | F11: =SUM(INDEX(Motore_Startup!$M$5:$M$544,(Ipotesi!$C$5-1)*60+3*12+1):INDEX(Motore_Startup!$M$5:$M$544,((Ipotesi!$C$5-1)*60+3*12+1)+11)) -> -307724.85 | G11: =SUM(INDEX(Motore_Startup!$M$5:$M$544,(Ipotesi!$C$5-1)*60+4*12+1):INDEX(Motore_Startup!$M$5:$M$544,((Ipotesi!$C$5-1)*60+4*12+1)+11)) -> -25579.277
A12: Contributo SS gestionale | B12: € | C12: =SUM(INDEX(Motore_Startup!$N$5:$N$544,(Ipotesi!$C$5-1)*60+0*12+1):INDEX(Motore_Startup!$N$5:$N$544,((Ipotesi!$C$5-1)*60+0*12+1)+11)) -> 14322.667 | D12: =SUM(INDEX(Motore_Startup!$N$5:$N$544,(Ipotesi!$C$5-1)*60+1*12+1):INDEX(Motore_Startup!$N$5:$N$544,((Ipotesi!$C$5-1)*60+1*12+1)+11)) -> 52143.783 | E12: =SUM(INDEX(Motore_Startup!$N$5:$N$544,(Ipotesi!$C$5-1)*60+2*12+1):INDEX(Motore_Startup!$N$5:$N$544,((Ipotesi!$C$5-1)*60+2*12+1)+11)) -> 36987.692 | F12: =SUM(INDEX(Motore_Startup!$N$5:$N$544,(Ipotesi!$C$5-1)*60+3*12+1):INDEX(Motore_Startup!$N$5:$N$544,((Ipotesi!$C$5-1)*60+3*12+1)+11)) -> 0 | G12: =SUM(INDEX(Motore_Startup!$N$5:$N$544,(Ipotesi!$C$5-1)*60+4*12+1):INDEX(Motore_Startup!$N$5:$N$544,((Ipotesi!$C$5-1)*60+4*12+1)+11)) -> 0
A13: Interessi e commissioni | B13: € | C13: =SUM(INDEX(Motore_Startup!$O$5:$O$544,(Ipotesi!$C$5-1)*60+0*12+1):INDEX(Motore_Startup!$O$5:$O$544,((Ipotesi!$C$5-1)*60+0*12+1)+11)) -> 2032.2039 | D13: =SUM(INDEX(Motore_Startup!$O$5:$O$544,(Ipotesi!$C$5-1)*60+1*12+1):INDEX(Motore_Startup!$O$5:$O$544,((Ipotesi!$C$5-1)*60+1*12+1)+11)) -> 5539.1636 | E13: =SUM(INDEX(Motore_Startup!$O$5:$O$544,(Ipotesi!$C$5-1)*60+2*12+1):INDEX(Motore_Startup!$O$5:$O$544,((Ipotesi!$C$5-1)*60+2*12+1)+11)) -> 2621.31 | F13: =SUM(INDEX(Motore_Startup!$O$5:$O$544,(Ipotesi!$C$5-1)*60+3*12+1):INDEX(Motore_Startup!$O$5:$O$544,((Ipotesi!$C$5-1)*60+3*12+1)+11)) -> 0 | G13: =SUM(INDEX(Motore_Startup!$O$5:$O$544,(Ipotesi!$C$5-1)*60+4*12+1):INDEX(Motore_Startup!$O$5:$O$544,((Ipotesi!$C$5-1)*60+4*12+1)+11)) -> 5738.2277
A14: Risultato ante imposte | B14: € | C14: =SUM(INDEX(Motore_Startup!$P$5:$P$544,(Ipotesi!$C$5-1)*60+0*12+1):INDEX(Motore_Startup!$P$5:$P$544,((Ipotesi!$C$5-1)*60+0*12+1)+11)) -> -211501.6 | D14: =SUM(INDEX(Motore_Startup!$P$5:$P$544,(Ipotesi!$C$5-1)*60+1*12+1):INDEX(Motore_Startup!$P$5:$P$544,((Ipotesi!$C$5-1)*60+1*12+1)+11)) -> -288925.79 | E14: =SUM(INDEX(Motore_Startup!$P$5:$P$544,(Ipotesi!$C$5-1)*60+2*12+1):INDEX(Motore_Startup!$P$5:$P$544,((Ipotesi!$C$5-1)*60+2*12+1)+11)) -> -507092.91 | F14: =SUM(INDEX(Motore_Startup!$P$5:$P$544,(Ipotesi!$C$5-1)*60+3*12+1):INDEX(Motore_Startup!$P$5:$P$544,((Ipotesi!$C$5-1)*60+3*12+1)+11)) -> -307724.85 | G14: =SUM(INDEX(Motore_Startup!$P$5:$P$544,(Ipotesi!$C$5-1)*60+4*12+1):INDEX(Motore_Startup!$P$5:$P$544,((Ipotesi!$C$5-1)*60+4*12+1)+11)) -> -31317.505
A15: Imposte CE | B15: € | C15: =SUM(INDEX(Motore_Startup!$X$5:$X$544,(Ipotesi!$C$5-1)*60+0*12+1):INDEX(Motore_Startup!$X$5:$X$544,((Ipotesi!$C$5-1)*60+0*12+1)+11)) -> 0 | D15: =SUM(INDEX(Motore_Startup!$X$5:$X$544,(Ipotesi!$C$5-1)*60+1*12+1):INDEX(Motore_Startup!$X$5:$X$544,((Ipotesi!$C$5-1)*60+1*12+1)+11)) -> 0 | E15: =SUM(INDEX(Motore_Startup!$X$5:$X$544,(Ipotesi!$C$5-1)*60+2*12+1):INDEX(Motore_Startup!$X$5:$X$544,((Ipotesi!$C$5-1)*60+2*12+1)+11)) -> 0 | F15: =SUM(INDEX(Motore_Startup!$X$5:$X$544,(Ipotesi!$C$5-1)*60+3*12+1):INDEX(Motore_Startup!$X$5:$X$544,((Ipotesi!$C$5-1)*60+3*12+1)+11)) -> 0 | G15: =SUM(INDEX(Motore_Startup!$X$5:$X$544,(Ipotesi!$C$5-1)*60+4*12+1):INDEX(Motore_Startup!$X$5:$X$544,((Ipotesi!$C$5-1)*60+4*12+1)+11)) -> 0
A16: Utile netto | B16: € | C16: =SUM(INDEX(Motore_Startup!$Y$5:$Y$544,(Ipotesi!$C$5-1)*60+0*12+1):INDEX(Motore_Startup!$Y$5:$Y$544,((Ipotesi!$C$5-1)*60+0*12+1)+11)) -> -211501.6 | D16: =SUM(INDEX(Motore_Startup!$Y$5:$Y$544,(Ipotesi!$C$5-1)*60+1*12+1):INDEX(Motore_Startup!$Y$5:$Y$544,((Ipotesi!$C$5-1)*60+1*12+1)+11)) -> -288925.79 | E16: =SUM(INDEX(Motore_Startup!$Y$5:$Y$544,(Ipotesi!$C$5-1)*60+2*12+1):INDEX(Motore_Startup!$Y$5:$Y$544,((Ipotesi!$C$5-1)*60+2*12+1)+11)) -> -507092.91 | F16: =SUM(INDEX(Motore_Startup!$Y$5:$Y$544,(Ipotesi!$C$5-1)*60+3*12+1):INDEX(Motore_Startup!$Y$5:$Y$544,((Ipotesi!$C$5-1)*60+3*12+1)+11)) -> -307724.85 | G16: =SUM(INDEX(Motore_Startup!$Y$5:$Y$544,(Ipotesi!$C$5-1)*60+4*12+1):INDEX(Motore_Startup!$Y$5:$Y$544,((Ipotesi!$C$5-1)*60+4*12+1)+11)) -> -31317.505
A18: Cassa teorica a fine anno / deficit | B18: € | C18: =INDEX(Motore_Startup!$BH$5:$BH$544,((Ipotesi!$C$5-1)*60+0*12+1)+11) -> 25000 | D18: =INDEX(Motore_Startup!$BH$5:$BH$544,((Ipotesi!$C$5-1)*60+1*12+1)+11) -> 40136.79 | E18: =INDEX(Motore_Startup!$BH$5:$BH$544,((Ipotesi!$C$5-1)*60+2*12+1)+11) -> 448452.52 | F18: =INDEX(Motore_Startup!$BH$5:$BH$544,((Ipotesi!$C$5-1)*60+3*12+1)+11) -> 28722.381 | G18: =INDEX(Motore_Startup!$BH$5:$BH$544,((Ipotesi!$C$5-1)*60+4*12+1)+11) -> 25000
A19: Minimo mensile di cassa nell'anno | B19: € | C19: =MIN(INDEX(Motore_Startup!$BH$5:$BH$544,(Ipotesi!$C$5-1)*60+0*12+1):INDEX(Motore_Startup!$BH$5:$BH$544,((Ipotesi!$C$5-1)*60+0*12+1)+11)) -> 25000 | D19: =MIN(INDEX(Motore_Startup!$BH$5:$BH$544,(Ipotesi!$C$5-1)*60+1*12+1):INDEX(Motore_Startup!$BH$5:$BH$544,((Ipotesi!$C$5-1)*60+1*12+1)+11)) -> -73138.76 | E19: =MIN(INDEX(Motore_Startup!$BH$5:$BH$544,(Ipotesi!$C$5-1)*60+2*12+1):INDEX(Motore_Startup!$BH$5:$BH$544,((Ipotesi!$C$5-1)*60+2*12+1)+11)) -> -73078.563 | F19: =MIN(INDEX(Motore_Startup!$BH$5:$BH$544,(Ipotesi!$C$5-1)*60+3*12+1):INDEX(Motore_Startup!$BH$5:$BH$544,((Ipotesi!$C$5-1)*60+3*12+1)+11)) -> 28722.381 | G19: =MIN(INDEX(Motore_Startup!$BH$5:$BH$544,(Ipotesi!$C$5-1)*60+4*12+1):INDEX(Motore_Startup!$BH$5:$BH$544,((Ipotesi!$C$5-1)*60+4*12+1)+11)) -> 25000
A20: Massimo fabbisogno per buffer nell'anno | B20: € | C20: =MAX(INDEX(Motore_Startup!$BI$5:$BI$544,(Ipotesi!$C$5-1)*60+0*12+1):INDEX(Motore_Startup!$BI$5:$BI$544,((Ipotesi!$C$5-1)*60+0*12+1)+11)) -> 0 | D20: =MAX(INDEX(Motore_Startup!$BI$5:$BI$544,(Ipotesi!$C$5-1)*60+1*12+1):INDEX(Motore_Startup!$BI$5:$BI$544,((Ipotesi!$C$5-1)*60+1*12+1)+11)) -> 98138.76 | E20: =MAX(INDEX(Motore_Startup!$BI$5:$BI$544,(Ipotesi!$C$5-1)*60+2*12+1):INDEX(Motore_Startup!$BI$5:$BI$544,((Ipotesi!$C$5-1)*60+2*12+1)+11)) -> 98078.563 | F20: =MAX(INDEX(Motore_Startup!$BI$5:$BI$544,(Ipotesi!$C$5-1)*60+3*12+1):INDEX(Motore_Startup!$BI$5:$BI$544,((Ipotesi!$C$5-1)*60+3*12+1)+11)) -> 0 | G20: =MAX(INDEX(Motore_Startup!$BI$5:$BI$544,(Ipotesi!$C$5-1)*60+4*12+1):INDEX(Motore_Startup!$BI$5:$BI$544,((Ipotesi!$C$5-1)*60+4*12+1)+11)) -> 0
A21: Fido utilizzato a fine anno | B21: € | C21: =INDEX(Motore_Startup!$BG$5:$BG$544,((Ipotesi!$C$5-1)*60+0*12+1)+11) -> 83960.882 | D21: =INDEX(Motore_Startup!$BG$5:$BG$544,((Ipotesi!$C$5-1)*60+1*12+1)+11) -> 0 | E21: =INDEX(Motore_Startup!$BG$5:$BG$544,((Ipotesi!$C$5-1)*60+2*12+1)+11) -> 0 | F21: =INDEX(Motore_Startup!$BG$5:$BG$544,((Ipotesi!$C$5-1)*60+3*12+1)+11) -> 0 | G21: =INDEX(Motore_Startup!$BG$5:$BG$544,((Ipotesi!$C$5-1)*60+4*12+1)+11) -> 111879
A22: SS erogato nell'anno | B22: € | C22: =SUM(INDEX(Motore_Startup!$BA$5:$BA$544,(Ipotesi!$C$5-1)*60+0*12+1):INDEX(Motore_Startup!$BA$5:$BA$544,((Ipotesi!$C$5-1)*60+0*12+1)+11)) -> 52542.222 | D22: =SUM(INDEX(Motore_Startup!$BA$5:$BA$544,(Ipotesi!$C$5-1)*60+1*12+1):INDEX(Motore_Startup!$BA$5:$BA$544,((Ipotesi!$C$5-1)*60+1*12+1)+11)) -> 190079.28 | E22: =SUM(INDEX(Motore_Startup!$BA$5:$BA$544,(Ipotesi!$C$5-1)*60+2*12+1):INDEX(Motore_Startup!$BA$5:$BA$544,((Ipotesi!$C$5-1)*60+2*12+1)+11)) -> 126225.64 | F22: =SUM(INDEX(Motore_Startup!$BA$5:$BA$544,(Ipotesi!$C$5-1)*60+3*12+1):INDEX(Motore_Startup!$BA$5:$BA$544,((Ipotesi!$C$5-1)*60+3*12+1)+11)) -> 0 | G22: =SUM(INDEX(Motore_Startup!$BA$5:$BA$544,(Ipotesi!$C$5-1)*60+4*12+1):INDEX(Motore_Startup!$BA$5:$BA$544,((Ipotesi!$C$5-1)*60+4*12+1)+11)) -> 0
A23: SS rimborsato nell'anno | B23: € | C23: =SUM(INDEX(Motore_Startup!$BB$5:$BB$544,(Ipotesi!$C$5-1)*60+0*12+1):INDEX(Motore_Startup!$BB$5:$BB$544,((Ipotesi!$C$5-1)*60+0*12+1)+11)) -> 0 | D23: =SUM(INDEX(Motore_Startup!$BB$5:$BB$544,(Ipotesi!$C$5-1)*60+1*12+1):INDEX(Motore_Startup!$BB$5:$BB$544,((Ipotesi!$C$5-1)*60+1*12+1)+11)) -> 0 | E23: =SUM(INDEX(Motore_Startup!$BB$5:$BB$544,(Ipotesi!$C$5-1)*60+2*12+1):INDEX(Motore_Startup!$BB$5:$BB$544,((Ipotesi!$C$5-1)*60+2*12+1)+11)) -> 0 | F23: =SUM(INDEX(Motore_Startup!$BB$5:$BB$544,(Ipotesi!$C$5-1)*60+3*12+1):INDEX(Motore_Startup!$BB$5:$BB$544,((Ipotesi!$C$5-1)*60+3*12+1)+11)) -> 26539.3 | G23: =SUM(INDEX(Motore_Startup!$BB$5:$BB$544,(Ipotesi!$C$5-1)*60+4*12+1):INDEX(Motore_Startup!$BB$5:$BB$544,((Ipotesi!$C$5-1)*60+4*12+1)+11)) -> 26539.3
A24: Debito SS residuo | B24: € | C24: =INDEX(Motore_Startup!$BC$5:$BC$544,((Ipotesi!$C$5-1)*60+0*12+1)+11) -> 38219.556 | D24: =INDEX(Motore_Startup!$BC$5:$BC$544,((Ipotesi!$C$5-1)*60+1*12+1)+11) -> 176155.05 | E24: =INDEX(Motore_Startup!$BC$5:$BC$544,((Ipotesi!$C$5-1)*60+2*12+1)+11) -> 265393 | F24: =INDEX(Motore_Startup!$BC$5:$BC$544,((Ipotesi!$C$5-1)*60+3*12+1)+11) -> 238853.7 | G24: =INDEX(Motore_Startup!$BC$5:$BC$544,((Ipotesi!$C$5-1)*60+4*12+1)+11) -> 212314.4
A25: Apporti iniziali | B25: € | C25: =SUM(INDEX(Motore_Startup!$AW$5:$AW$544,(Ipotesi!$C$5-1)*60+0*12+1):INDEX(Motore_Startup!$AW$5:$AW$544,((Ipotesi!$C$5-1)*60+0*12+1)+11)) -> 130000 | D25: =SUM(INDEX(Motore_Startup!$AW$5:$AW$544,(Ipotesi!$C$5-1)*60+1*12+1):INDEX(Motore_Startup!$AW$5:$AW$544,((Ipotesi!$C$5-1)*60+1*12+1)+11)) -> 0 | E25: =SUM(INDEX(Motore_Startup!$AW$5:$AW$544,(Ipotesi!$C$5-1)*60+2*12+1):INDEX(Motore_Startup!$AW$5:$AW$544,((Ipotesi!$C$5-1)*60+2*12+1)+11)) -> 0 | F25: =SUM(INDEX(Motore_Startup!$AW$5:$AW$544,(Ipotesi!$C$5-1)*60+3*12+1):INDEX(Motore_Startup!$AW$5:$AW$544,((Ipotesi!$C$5-1)*60+3*12+1)+11)) -> 0 | G25: =SUM(INDEX(Motore_Startup!$AW$5:$AW$544,(Ipotesi!$C$5-1)*60+4*12+1):INDEX(Motore_Startup!$AW$5:$AW$544,((Ipotesi!$C$5-1)*60+4*12+1)+11)) -> 0
A26: Round incassati | B26: € | C26: =SUM(INDEX(Motore_Startup!$AX$5:$AX$544,(Ipotesi!$C$5-1)*60+0*12+1):INDEX(Motore_Startup!$AX$5:$AX$544,((Ipotesi!$C$5-1)*60+0*12+1)+11)) -> 0 | D26: =SUM(INDEX(Motore_Startup!$AX$5:$AX$544,(Ipotesi!$C$5-1)*60+1*12+1):INDEX(Motore_Startup!$AX$5:$AX$544,((Ipotesi!$C$5-1)*60+1*12+1)+11)) -> 300000 | E26: =SUM(INDEX(Motore_Startup!$AX$5:$AX$544,(Ipotesi!$C$5-1)*60+2*12+1):INDEX(Motore_Startup!$AX$5:$AX$544,((Ipotesi!$C$5-1)*60+2*12+1)+11)) -> 900000 | F26: =SUM(INDEX(Motore_Startup!$AX$5:$AX$544,(Ipotesi!$C$5-1)*60+3*12+1):INDEX(Motore_Startup!$AX$5:$AX$544,((Ipotesi!$C$5-1)*60+3*12+1)+11)) -> 0 | G26: =SUM(INDEX(Motore_Startup!$AX$5:$AX$544,(Ipotesi!$C$5-1)*60+4*12+1):INDEX(Motore_Startup!$AX$5:$AX$544,((Ipotesi!$C$5-1)*60+4*12+1)+11)) -> 0
A27: Dividendi lordi distribuiti | B27: € | C27: =SUM(INDEX(Motore_Startup!$AY$5:$AY$544,(Ipotesi!$C$5-1)*60+0*12+1):INDEX(Motore_Startup!$AY$5:$AY$544,((Ipotesi!$C$5-1)*60+0*12+1)+11)) -> 0 | D27: =SUM(INDEX(Motore_Startup!$AY$5:$AY$544,(Ipotesi!$C$5-1)*60+1*12+1):INDEX(Motore_Startup!$AY$5:$AY$544,((Ipotesi!$C$5-1)*60+1*12+1)+11)) -> 0 | E27: =SUM(INDEX(Motore_Startup!$AY$5:$AY$544,(Ipotesi!$C$5-1)*60+2*12+1):INDEX(Motore_Startup!$AY$5:$AY$544,((Ipotesi!$C$5-1)*60+2*12+1)+11)) -> 0 | F27: =SUM(INDEX(Motore_Startup!$AY$5:$AY$544,(Ipotesi!$C$5-1)*60+3*12+1):INDEX(Motore_Startup!$AY$5:$AY$544,((Ipotesi!$C$5-1)*60+3*12+1)+11)) -> 0 | G27: =SUM(INDEX(Motore_Startup!$AY$5:$AY$544,(Ipotesi!$C$5-1)*60+4*12+1):INDEX(Motore_Startup!$AY$5:$AY$544,((Ipotesi!$C$5-1)*60+4*12+1)+11)) -> 0
A28: Dividendi reinvestiti dai soci | B28: € | C28: =SUM(INDEX(Motore_Startup!$AZ$5:$AZ$544,(Ipotesi!$C$5-1)*60+0*12+1):INDEX(Motore_Startup!$AZ$5:$AZ$544,((Ipotesi!$C$5-1)*60+0*12+1)+11)) -> 0 | D28: =SUM(INDEX(Motore_Startup!$AZ$5:$AZ$544,(Ipotesi!$C$5-1)*60+1*12+1):INDEX(Motore_Startup!$AZ$5:$AZ$544,((Ipotesi!$C$5-1)*60+1*12+1)+11)) -> 0 | E28: =SUM(INDEX(Motore_Startup!$AZ$5:$AZ$544,(Ipotesi!$C$5-1)*60+2*12+1):INDEX(Motore_Startup!$AZ$5:$AZ$544,((Ipotesi!$C$5-1)*60+2*12+1)+11)) -> 0 | F28: =SUM(INDEX(Motore_Startup!$AZ$5:$AZ$544,(Ipotesi!$C$5-1)*60+3*12+1):INDEX(Motore_Startup!$AZ$5:$AZ$544,((Ipotesi!$C$5-1)*60+3*12+1)+11)) -> 35707.016 | G28: =SUM(INDEX(Motore_Startup!$AZ$5:$AZ$544,(Ipotesi!$C$5-1)*60+4*12+1):INDEX(Motore_Startup!$AZ$5:$AZ$544,((Ipotesi!$C$5-1)*60+4*12+1)+11)) -> 69723.393
A30: Crediti esterni IVA inclusa | B30: € | C30: =INDEX(Motore_Startup!$AD$5:$AD$544,((Ipotesi!$C$5-1)*60+0*12+1)+11) -> 29991.667 | D30: =INDEX(Motore_Startup!$AD$5:$AD$544,((Ipotesi!$C$5-1)*60+1*12+1)+11) -> 113239.53 | E30: =INDEX(Motore_Startup!$AD$5:$AD$544,((Ipotesi!$C$5-1)*60+2*12+1)+11) -> 286627 | F30: =INDEX(Motore_Startup!$AD$5:$AD$544,((Ipotesi!$C$5-1)*60+3*12+1)+11) -> 504631.67 | G30: =INDEX(Motore_Startup!$AD$5:$AD$544,((Ipotesi!$C$5-1)*60+4*12+1)+11) -> 743698.48
A31: Saldo infragruppo | B31: € | C31: =INDEX(Motore_Startup!$AG$5:$AG$544,((Ipotesi!$C$5-1)*60+0*12+1)+11) -> 1977.6842 | D31: =INDEX(Motore_Startup!$AG$5:$AG$544,((Ipotesi!$C$5-1)*60+1*12+1)+11) -> 4145.7089 | E31: =INDEX(Motore_Startup!$AG$5:$AG$544,((Ipotesi!$C$5-1)*60+2*12+1)+11) -> 7381 | F31: =INDEX(Motore_Startup!$AG$5:$AG$544,((Ipotesi!$C$5-1)*60+3*12+1)+11) -> 11009.483 | G31: =INDEX(Motore_Startup!$AG$5:$AG$544,((Ipotesi!$C$5-1)*60+4*12+1)+11) -> 14146.917
A32: Debiti fornitori esterni | B32: € | C32: =INDEX(Motore_Startup!$AJ$5:$AJ$544,((Ipotesi!$C$5-1)*60+0*12+1)+11) -> 23562.548 | D32: =INDEX(Motore_Startup!$AJ$5:$AJ$544,((Ipotesi!$C$5-1)*60+1*12+1)+11) -> 43547.568 | E32: =INDEX(Motore_Startup!$AJ$5:$AJ$544,((Ipotesi!$C$5-1)*60+2*12+1)+11) -> 104937.84 | F32: =INDEX(Motore_Startup!$AJ$5:$AJ$544,((Ipotesi!$C$5-1)*60+3*12+1)+11) -> 148703.05 | G32: =INDEX(Motore_Startup!$AJ$5:$AJ$544,((Ipotesi!$C$5-1)*60+4*12+1)+11) -> 194334.47
A33: Saldo IVA (debito + / credito -) | B33: € | C33: =INDEX(Motore_Startup!$AM$5:$AM$544,((Ipotesi!$C$5-1)*60+0*12+1)+11) -> -1633.1503 | D33: =INDEX(Motore_Startup!$AM$5:$AM$544,((Ipotesi!$C$5-1)*60+1*12+1)+11) -> 3847.6305 | E33: =INDEX(Motore_Startup!$AM$5:$AM$544,((Ipotesi!$C$5-1)*60+2*12+1)+11) -> 10269.946 | F33: =INDEX(Motore_Startup!$AM$5:$AM$544,((Ipotesi!$C$5-1)*60+3*12+1)+11) -> 20469.921 | G33: =INDEX(Motore_Startup!$AM$5:$AM$544,((Ipotesi!$C$5-1)*60+4*12+1)+11) -> 31707.815
A34: Saldo imposte (debito + / credito -) | B34: € | C34: =INDEX(Motore_Startup!$AR$5:$AR$544,((Ipotesi!$C$5-1)*60+0*12+1)+11) -> 0 | D34: =INDEX(Motore_Startup!$AR$5:$AR$544,((Ipotesi!$C$5-1)*60+1*12+1)+11) -> 0 | E34: =INDEX(Motore_Startup!$AR$5:$AR$544,((Ipotesi!$C$5-1)*60+2*12+1)+11) -> 0 | F34: =INDEX(Motore_Startup!$AR$5:$AR$544,((Ipotesi!$C$5-1)*60+3*12+1)+11) -> 0 | G34: =INDEX(Motore_Startup!$AR$5:$AR$544,((Ipotesi!$C$5-1)*60+4*12+1)+11) -> 0
A35: Fondo TFR | B35: € | C35: =INDEX(Motore_Startup!$AV$5:$AV$544,((Ipotesi!$C$5-1)*60+0*12+1)+11) -> 10750 | D35: =INDEX(Motore_Startup!$AV$5:$AV$544,((Ipotesi!$C$5-1)*60+1*12+1)+11) -> 34607.5 | E35: =INDEX(Motore_Startup!$AV$5:$AV$544,((Ipotesi!$C$5-1)*60+2*12+1)+11) -> 79171.7 | F35: =INDEX(Motore_Startup!$AV$5:$AV$544,((Ipotesi!$C$5-1)*60+3*12+1)+11) -> 137055.55 | G35: =INDEX(Motore_Startup!$AV$5:$AV$544,((Ipotesi!$C$5-1)*60+4*12+1)+11) -> 208741.95
A36: Immobilizzazioni nette | B36: € | C36: =INDEX(Motore_Startup!$BL$5:$BL$544,((Ipotesi!$C$5-1)*60+0*12+1)+11) -> 16388.889 | D36: =INDEX(Motore_Startup!$BL$5:$BL$544,((Ipotesi!$C$5-1)*60+1*12+1)+11) -> 30208.333 | E36: =INDEX(Motore_Startup!$BL$5:$BL$544,((Ipotesi!$C$5-1)*60+2*12+1)+11) -> 39791.667 | F36: =INDEX(Motore_Startup!$BL$5:$BL$544,((Ipotesi!$C$5-1)*60+3*12+1)+11) -> 51180.556 | G36: =INDEX(Motore_Startup!$BL$5:$BL$544,((Ipotesi!$C$5-1)*60+4*12+1)+11) -> 65000
A37: Patrimonio netto | B37: € | C37: =INDEX(Motore_Startup!$BQ$5:$BQ$544,((Ipotesi!$C$5-1)*60+0*12+1)+11) -> -81501.596 | D37: =INDEX(Motore_Startup!$BQ$5:$BQ$544,((Ipotesi!$C$5-1)*60+1*12+1)+11) -> -70427.385 | E37: =INDEX(Motore_Startup!$BQ$5:$BQ$544,((Ipotesi!$C$5-1)*60+2*12+1)+11) -> 322479.7 | F37: =INDEX(Motore_Startup!$BQ$5:$BQ$544,((Ipotesi!$C$5-1)*60+3*12+1)+11) -> 50461.874 | G37: =INDEX(Motore_Startup!$BQ$5:$BQ$544,((Ipotesi!$C$5-1)*60+4*12+1)+11) -> 88867.762
A38: Totale attività teoriche | B38: € | C38: =INDEX(Motore_Startup!$BR$5:$BR$544,((Ipotesi!$C$5-1)*60+0*12+1)+11) -> 74991.39 | D38: =INDEX(Motore_Startup!$BR$5:$BR$544,((Ipotesi!$C$5-1)*60+1*12+1)+11) -> 187730.36 | E38: =INDEX(Motore_Startup!$BR$5:$BR$544,((Ipotesi!$C$5-1)*60+2*12+1)+11) -> 782252.19 | F38: =INDEX(Motore_Startup!$BR$5:$BR$544,((Ipotesi!$C$5-1)*60+3*12+1)+11) -> 595544.09 | G38: =INDEX(Motore_Startup!$BR$5:$BR$544,((Ipotesi!$C$5-1)*60+4*12+1)+11) -> 847845.4
A39: Passività e patrimonio netto | B39: € | C39: =INDEX(Motore_Startup!$BS$5:$BS$544,((Ipotesi!$C$5-1)*60+0*12+1)+11) -> 74991.39 | D39: =INDEX(Motore_Startup!$BS$5:$BS$544,((Ipotesi!$C$5-1)*60+1*12+1)+11) -> 187730.36 | E39: =INDEX(Motore_Startup!$BS$5:$BS$544,((Ipotesi!$C$5-1)*60+2*12+1)+11) -> 782252.19 | F39: =INDEX(Motore_Startup!$BS$5:$BS$544,((Ipotesi!$C$5-1)*60+3*12+1)+11) -> 595544.09 | G39: =INDEX(Motore_Startup!$BS$5:$BS$544,((Ipotesi!$C$5-1)*60+4*12+1)+11) -> 847845.4
A40: Quadratura SP fine anno | B40: € | C40: =INDEX(Motore_Startup!$BT$5:$BT$544,((Ipotesi!$C$5-1)*60+0*12+1)+11) -> 0 | D40: =INDEX(Motore_Startup!$BT$5:$BT$544,((Ipotesi!$C$5-1)*60+1*12+1)+11) -> 0 | E40: =INDEX(Motore_Startup!$BT$5:$BT$544,((Ipotesi!$C$5-1)*60+2*12+1)+11) -> 0 | F40: =INDEX(Motore_Startup!$BT$5:$BT$544,((Ipotesi!$C$5-1)*60+3*12+1)+11) -> 0 | G40: =INDEX(Motore_Startup!$BT$5:$BT$544,((Ipotesi!$C$5-1)*60+4*12+1)+11) -> 0
A42: Investimenti pagati ex IVA | B42: € | C42: =SUM(INDEX(Motore_Startup!$K$5:$K$544,(Ipotesi!$C$5-1)*60+0*12+1):INDEX(Motore_Startup!$K$5:$K$544,((Ipotesi!$C$5-1)*60+0*12+1)+11)) -> 20000 | D42: =SUM(INDEX(Motore_Startup!$K$5:$K$544,(Ipotesi!$C$5-1)*60+1*12+1):INDEX(Motore_Startup!$K$5:$K$544,((Ipotesi!$C$5-1)*60+1*12+1)+11)) -> 25000 | E42: =SUM(INDEX(Motore_Startup!$K$5:$K$544,(Ipotesi!$C$5-1)*60+2*12+1):INDEX(Motore_Startup!$K$5:$K$544,((Ipotesi!$C$5-1)*60+2*12+1)+11)) -> 30000 | F42: =SUM(INDEX(Motore_Startup!$K$5:$K$544,(Ipotesi!$C$5-1)*60+3*12+1):INDEX(Motore_Startup!$K$5:$K$544,((Ipotesi!$C$5-1)*60+3*12+1)+11)) -> 40000 | G42: =SUM(INDEX(Motore_Startup!$K$5:$K$544,(Ipotesi!$C$5-1)*60+4*12+1):INDEX(Motore_Startup!$K$5:$K$544,((Ipotesi!$C$5-1)*60+4*12+1)+11)) -> 50000
A43: Imposte effettivamente pagate | B43: € | C43: =SUM(INDEX(Motore_Startup!$AQ$5:$AQ$544,(Ipotesi!$C$5-1)*60+0*12+1):INDEX(Motore_Startup!$AQ$5:$AQ$544,((Ipotesi!$C$5-1)*60+0*12+1)+11)) -> 0 | D43: =SUM(INDEX(Motore_Startup!$AQ$5:$AQ$544,(Ipotesi!$C$5-1)*60+1*12+1):INDEX(Motore_Startup!$AQ$5:$AQ$544,((Ipotesi!$C$5-1)*60+1*12+1)+11)) -> 0 | E43: =SUM(INDEX(Motore_Startup!$AQ$5:$AQ$544,(Ipotesi!$C$5-1)*60+2*12+1):INDEX(Motore_Startup!$AQ$5:$AQ$544,((Ipotesi!$C$5-1)*60+2*12+1)+11)) -> 0 | F43: =SUM(INDEX(Motore_Startup!$AQ$5:$AQ$544,(Ipotesi!$C$5-1)*60+3*12+1):INDEX(Motore_Startup!$AQ$5:$AQ$544,((Ipotesi!$C$5-1)*60+3*12+1)+11)) -> 0 | G43: =SUM(INDEX(Motore_Startup!$AQ$5:$AQ$544,(Ipotesi!$C$5-1)*60+4*12+1):INDEX(Motore_Startup!$AQ$5:$AQ$544,((Ipotesi!$C$5-1)*60+4*12+1)+11)) -> 0
A44: IVA versata | B44: € | C44: =SUM(INDEX(Motore_Startup!$AL$5:$AL$544,(Ipotesi!$C$5-1)*60+0*12+1):INDEX(Motore_Startup!$AL$5:$AL$544,((Ipotesi!$C$5-1)*60+0*12+1)+11)) -> 0 | D44: =SUM(INDEX(Motore_Startup!$AL$5:$AL$544,(Ipotesi!$C$5-1)*60+1*12+1):INDEX(Motore_Startup!$AL$5:$AL$544,((Ipotesi!$C$5-1)*60+1*12+1)+11)) -> 29660.664 | E44: =SUM(INDEX(Motore_Startup!$AL$5:$AL$544,(Ipotesi!$C$5-1)*60+2*12+1):INDEX(Motore_Startup!$AL$5:$AL$544,((Ipotesi!$C$5-1)*60+2*12+1)+11)) -> 85253.028 | F44: =SUM(INDEX(Motore_Startup!$AL$5:$AL$544,(Ipotesi!$C$5-1)*60+3*12+1):INDEX(Motore_Startup!$AL$5:$AL$544,((Ipotesi!$C$5-1)*60+3*12+1)+11)) -> 198282.89 | G44: =SUM(INDEX(Motore_Startup!$AL$5:$AL$544,(Ipotesi!$C$5-1)*60+4*12+1):INDEX(Motore_Startup!$AL$5:$AL$544,((Ipotesi!$C$5-1)*60+4*12+1)+11)) -> 327014.55
...

Sheet Advisory
A1: Advisory | riepilogo annuale selezionato
A2: Patrimonio e cassa autonomi: non sono liberamente trasferibili tra le società.
A4: Indicatore | B4: Unità | C4: 2027 | D4: 2028 | E4: 2029 | F4: 2030 | G4: 2031
A5: Ricavi esterni | B5: € | C5: =SUM(INDEX(Motore_Advisory!$F$5:$F$544,(Ipotesi!$C$5-1)*60+0*12+1):INDEX(Motore_Advisory!$F$5:$F$544,((Ipotesi!$C$5-1)*60+0*12+1)+11)) -> 194526.32 | D5: =SUM(INDEX(Motore_Advisory!$F$5:$F$544,(Ipotesi!$C$5-1)*60+1*12+1):INDEX(Motore_Advisory!$F$5:$F$544,((Ipotesi!$C$5-1)*60+1*12+1)+11)) -> 407774.65 | E5: =SUM(INDEX(Motore_Advisory!$F$5:$F$544,(Ipotesi!$C$5-1)*60+2*12+1):INDEX(Motore_Advisory!$F$5:$F$544,((Ipotesi!$C$5-1)*60+2*12+1)+11)) -> 726000 | F5: =SUM(INDEX(Motore_Advisory!$F$5:$F$544,(Ipotesi!$C$5-1)*60+3*12+1):INDEX(Motore_Advisory!$F$5:$F$544,((Ipotesi!$C$5-1)*60+3*12+1)+11)) -> 1082900 | G5: =SUM(INDEX(Motore_Advisory!$F$5:$F$544,(Ipotesi!$C$5-1)*60+4*12+1):INDEX(Motore_Advisory!$F$5:$F$544,((Ipotesi!$C$5-1)*60+4*12+1)+11)) -> 1391500
A6: Canone infragruppo (ricavo S / costo A) | B6: € | C6: =SUM(INDEX(Motore_Advisory!$G$5:$G$544,(Ipotesi!$C$5-1)*60+0*12+1):INDEX(Motore_Advisory!$G$5:$G$544,((Ipotesi!$C$5-1)*60+0*12+1)+11)) -> 19452.632 | D6: =SUM(INDEX(Motore_Advisory!$G$5:$G$544,(Ipotesi!$C$5-1)*60+1*12+1):INDEX(Motore_Advisory!$G$5:$G$544,((Ipotesi!$C$5-1)*60+1*12+1)+11)) -> 40777.465 | E6: =SUM(INDEX(Motore_Advisory!$G$5:$G$544,(Ipotesi!$C$5-1)*60+2*12+1):INDEX(Motore_Advisory!$G$5:$G$544,((Ipotesi!$C$5-1)*60+2*12+1)+11)) -> 72600 | F6: =SUM(INDEX(Motore_Advisory!$G$5:$G$544,(Ipotesi!$C$5-1)*60+3*12+1):INDEX(Motore_Advisory!$G$5:$G$544,((Ipotesi!$C$5-1)*60+3*12+1)+11)) -> 108290 | G6: =SUM(INDEX(Motore_Advisory!$G$5:$G$544,(Ipotesi!$C$5-1)*60+4*12+1):INDEX(Motore_Advisory!$G$5:$G$544,((Ipotesi!$C$5-1)*60+4*12+1)+11)) -> 139150
A7: Ricavi conto economico | B7: € | C7: =SUM(INDEX(Motore_Advisory!$H$5:$H$544,(Ipotesi!$C$5-1)*60+0*12+1):INDEX(Motore_Advisory!$H$5:$H$544,((Ipotesi!$C$5-1)*60+0*12+1)+11)) -> 194526.32 | D7: =SUM(INDEX(Motore_Advisory!$H$5:$H$544,(Ipotesi!$C$5-1)*60+1*12+1):INDEX(Motore_Advisory!$H$5:$H$544,((Ipotesi!$C$5-1)*60+1*12+1)+11)) -> 407774.65 | E7: =SUM(INDEX(Motore_Advisory!$H$5:$H$544,(Ipotesi!$C$5-1)*60+2*12+1):INDEX(Motore_Advisory!$H$5:$H$544,((Ipotesi!$C$5-1)*60+2*12+1)+11)) -> 726000 | F7: =SUM(INDEX(Motore_Advisory!$H$5:$H$544,(Ipotesi!$C$5-1)*60+3*12+1):INDEX(Motore_Advisory!$H$5:$H$544,((Ipotesi!$C$5-1)*60+3*12+1)+11)) -> 1082900 | G7: =SUM(INDEX(Motore_Advisory!$H$5:$H$544,(Ipotesi!$C$5-1)*60+4*12+1):INDEX(Motore_Advisory!$H$5:$H$544,((Ipotesi!$C$5-1)*60+4*12+1)+11)) -> 1391500
A8: Costi operativi | B8: € | C8: =SUM(INDEX(Motore_Advisory!$I$5:$I$544,(Ipotesi!$C$5-1)*60+0*12+1):INDEX(Motore_Advisory!$I$5:$I$544,((Ipotesi!$C$5-1)*60+0*12+1)+11)) -> 145374.21 | D8: =SUM(INDEX(Motore_Advisory!$I$5:$I$544,(Ipotesi!$C$5-1)*60+1*12+1):INDEX(Motore_Advisory!$I$5:$I$544,((Ipotesi!$C$5-1)*60+1*12+1)+11)) -> 346623.94 | E8: =SUM(INDEX(Motore_Advisory!$I$5:$I$544,(Ipotesi!$C$5-1)*60+2*12+1):INDEX(Motore_Advisory!$I$5:$I$544,((Ipotesi!$C$5-1)*60+2*12+1)+11)) -> 555118.75 | F8: =SUM(INDEX(Motore_Advisory!$I$5:$I$544,(Ipotesi!$C$5-1)*60+3*12+1):INDEX(Motore_Advisory!$I$5:$I$544,((Ipotesi!$C$5-1)*60+3*12+1)+11)) -> 750962.08 | G8: =SUM(INDEX(Motore_Advisory!$I$5:$I$544,(Ipotesi!$C$5-1)*60+4*12+1):INDEX(Motore_Advisory!$I$5:$I$544,((Ipotesi!$C$5-1)*60+4*12+1)+11)) -> 955505.67
A9: EBITDA senza contributi | B9: € | C9: =SUM(INDEX(Motore_Advisory!$J$5:$J$544,(Ipotesi!$C$5-1)*60+0*12+1):INDEX(Motore_Advisory!$J$5:$J$544,((Ipotesi!$C$5-1)*60+0*12+1)+11)) -> 49152.105 | D9: =SUM(INDEX(Motore_Advisory!$J$5:$J$544,(Ipotesi!$C$5-1)*60+1*12+1):INDEX(Motore_Advisory!$J$5:$J$544,((Ipotesi!$C$5-1)*60+1*12+1)+11)) -> 61150.704 | E9: =SUM(INDEX(Motore_Advisory!$J$5:$J$544,(Ipotesi!$C$5-1)*60+2*12+1):INDEX(Motore_Advisory!$J$5:$J$544,((Ipotesi!$C$5-1)*60+2*12+1)+11)) -> 170881.25 | F9: =SUM(INDEX(Motore_Advisory!$J$5:$J$544,(Ipotesi!$C$5-1)*60+3*12+1):INDEX(Motore_Advisory!$J$5:$J$544,((Ipotesi!$C$5-1)*60+3*12+1)+11)) -> 331937.92 | G9: =SUM(INDEX(Motore_Advisory!$J$5:$J$544,(Ipotesi!$C$5-1)*60+4*12+1):INDEX(Motore_Advisory!$J$5:$J$544,((Ipotesi!$C$5-1)*60+4*12+1)+11)) -> 435994.33
A10: Ammortamenti | B10: € | C10: =SUM(INDEX(Motore_Advisory!$L$5:$L$544,(Ipotesi!$C$5-1)*60+0*12+1):INDEX(Motore_Advisory!$L$5:$L$544,((Ipotesi!$C$5-1)*60+0*12+1)+11)) -> 541.66667 | D10: =SUM(INDEX(Motore_Advisory!$L$5:$L$544,(Ipotesi!$C$5-1)*60+1*12+1):INDEX(Motore_Advisory!$L$5:$L$544,((Ipotesi!$C$5-1)*60+1*12+1)+11)) -> 1902.7778 | E10: =SUM(INDEX(Motore_Advisory!$L$5:$L$544,(Ipotesi!$C$5-1)*60+2*12+1):INDEX(Motore_Advisory!$L$5:$L$544,((Ipotesi!$C$5-1)*60+2*12+1)+11)) -> 3569.4444 | F10: =SUM(INDEX(Motore_Advisory!$L$5:$L$544,(Ipotesi!$C$5-1)*60+3*12+1):INDEX(Motore_Advisory!$L$5:$L$544,((Ipotesi!$C$5-1)*60+3*12+1)+11)) -> 5236.1111 | G10: =SUM(INDEX(Motore_Advisory!$L$5:$L$544,(Ipotesi!$C$5-1)*60+4*12+1):INDEX(Motore_Advisory!$L$5:$L$544,((Ipotesi!$C$5-1)*60+4*12+1)+11)) -> 6541.6667
A11: EBIT | B11: € | C11: =SUM(INDEX(Motore_Advisory!$M$5:$M$544,(Ipotesi!$C$5-1)*60+0*12+1):INDEX(Motore_Advisory!$M$5:$M$544,((Ipotesi!$C$5-1)*60+0*12+1)+11)) -> 48610.439 | D11: =SUM(INDEX(Motore_Advisory!$M$5:$M$544,(Ipotesi!$C$5-1)*60+1*12+1):INDEX(Motore_Advisory!$M$5:$M$544,((Ipotesi!$C$5-1)*60+1*12+1)+11)) -> 59247.926 | E11: =SUM(INDEX(Motore_Advisory!$M$5:$M$544,(Ipotesi!$C$5-1)*60+2*12+1):INDEX(Motore_Advisory!$M$5:$M$544,((Ipotesi!$C$5-1)*60+2*12+1)+11)) -> 167311.81 | F11: =SUM(INDEX(Motore_Advisory!$M$5:$M$544,(Ipotesi!$C$5-1)*60+3*12+1):INDEX(Motore_Advisory!$M$5:$M$544,((Ipotesi!$C$5-1)*60+3*12+1)+11)) -> 326701.81 | G11: =SUM(INDEX(Motore_Advisory!$M$5:$M$544,(Ipotesi!$C$5-1)*60+4*12+1):INDEX(Motore_Advisory!$M$5:$M$544,((Ipotesi!$C$5-1)*60+4*12+1)+11)) -> 429452.67
A12: Contributo SS gestionale | B12: € | C12: =SUM(INDEX(Motore_Advisory!$N$5:$N$544,(Ipotesi!$C$5-1)*60+0*12+1):INDEX(Motore_Advisory!$N$5:$N$544,((Ipotesi!$C$5-1)*60+0*12+1)+11)) -> 0 | D12: =SUM(INDEX(Motore_Advisory!$N$5:$N$544,(Ipotesi!$C$5-1)*60+1*12+1):INDEX(Motore_Advisory!$N$5:$N$544,((Ipotesi!$C$5-1)*60+1*12+1)+11)) -> 0 | E12: =SUM(INDEX(Motore_Advisory!$N$5:$N$544,(Ipotesi!$C$5-1)*60+2*12+1):INDEX(Motore_Advisory!$N$5:$N$544,((Ipotesi!$C$5-1)*60+2*12+1)+11)) -> 0 | F12: =SUM(INDEX(Motore_Advisory!$N$5:$N$544,(Ipotesi!$C$5-1)*60+3*12+1):INDEX(Motore_Advisory!$N$5:$N$544,((Ipotesi!$C$5-1)*60+3*12+1)+11)) -> 0 | G12: =SUM(INDEX(Motore_Advisory!$N$5:$N$544,(Ipotesi!$C$5-1)*60+4*12+1):INDEX(Motore_Advisory!$N$5:$N$544,((Ipotesi!$C$5-1)*60+4*12+1)+11)) -> 0
A13: Interessi e commissioni | B13: € | C13: =SUM(INDEX(Motore_Advisory!$O$5:$O$544,(Ipotesi!$C$5-1)*60+0*12+1):INDEX(Motore_Advisory!$O$5:$O$544,((Ipotesi!$C$5-1)*60+0*12+1)+11)) -> 0 | D13: =SUM(INDEX(Motore_Advisory!$O$5:$O$544,(Ipotesi!$C$5-1)*60+1*12+1):INDEX(Motore_Advisory!$O$5:$O$544,((Ipotesi!$C$5-1)*60+1*12+1)+11)) -> 0 | E13: =SUM(INDEX(Motore_Advisory!$O$5:$O$544,(Ipotesi!$C$5-1)*60+2*12+1):INDEX(Motore_Advisory!$O$5:$O$544,((Ipotesi!$C$5-1)*60+2*12+1)+11)) -> 0 | F13: =SUM(INDEX(Motore_Advisory!$O$5:$O$544,(Ipotesi!$C$5-1)*60+3*12+1):INDEX(Motore_Advisory!$O$5:$O$544,((Ipotesi!$C$5-1)*60+3*12+1)+11)) -> 0 | G13: =SUM(INDEX(Motore_Advisory!$O$5:$O$544,(Ipotesi!$C$5-1)*60+4*12+1):INDEX(Motore_Advisory!$O$5:$O$544,((Ipotesi!$C$5-1)*60+4*12+1)+11)) -> 0
A14: Risultato ante imposte | B14: € | C14: =SUM(INDEX(Motore_Advisory!$P$5:$P$544,(Ipotesi!$C$5-1)*60+0*12+1):INDEX(Motore_Advisory!$P$5:$P$544,((Ipotesi!$C$5-1)*60+0*12+1)+11)) -> 48610.439 | D14: =SUM(INDEX(Motore_Advisory!$P$5:$P$544,(Ipotesi!$C$5-1)*60+1*12+1):INDEX(Motore_Advisory!$P$5:$P$544,((Ipotesi!$C$5-1)*60+1*12+1)+11)) -> 59247.926 | E14: =SUM(INDEX(Motore_Advisory!$P$5:$P$544,(Ipotesi!$C$5-1)*60+2*12+1):INDEX(Motore_Advisory!$P$5:$P$544,((Ipotesi!$C$5-1)*60+2*12+1)+11)) -> 167311.81 | F14: =SUM(INDEX(Motore_Advisory!$P$5:$P$544,(Ipotesi!$C$5-1)*60+3*12+1):INDEX(Motore_Advisory!$P$5:$P$544,((Ipotesi!$C$5-1)*60+3*12+1)+11)) -> 326701.81 | G14: =SUM(INDEX(Motore_Advisory!$P$5:$P$544,(Ipotesi!$C$5-1)*60+4*12+1):INDEX(Motore_Advisory!$P$5:$P$544,((Ipotesi!$C$5-1)*60+4*12+1)+11)) -> 429452.67
A15: Imposte CE | B15: € | C15: =SUM(INDEX(Motore_Advisory!$X$5:$X$544,(Ipotesi!$C$5-1)*60+0*12+1):INDEX(Motore_Advisory!$X$5:$X$544,((Ipotesi!$C$5-1)*60+0*12+1)+11)) -> 13562.312 | D15: =SUM(INDEX(Motore_Advisory!$X$5:$X$544,(Ipotesi!$C$5-1)*60+1*12+1):INDEX(Motore_Advisory!$X$5:$X$544,((Ipotesi!$C$5-1)*60+1*12+1)+11)) -> 16530.171 | E15: =SUM(INDEX(Motore_Advisory!$X$5:$X$544,(Ipotesi!$C$5-1)*60+2*12+1):INDEX(Motore_Advisory!$X$5:$X$544,((Ipotesi!$C$5-1)*60+2*12+1)+11)) -> 46679.994 | F15: =SUM(INDEX(Motore_Advisory!$X$5:$X$544,(Ipotesi!$C$5-1)*60+3*12+1):INDEX(Motore_Advisory!$X$5:$X$544,((Ipotesi!$C$5-1)*60+3*12+1)+11)) -> 91149.805 | G15: =SUM(INDEX(Motore_Advisory!$X$5:$X$544,(Ipotesi!$C$5-1)*60+4*12+1):INDEX(Motore_Advisory!$X$5:$X$544,((Ipotesi!$C$5-1)*60+4*12+1)+11)) -> 119817.29
A16: Utile netto | B16: € | C16: =SUM(INDEX(Motore_Advisory!$Y$5:$Y$544,(Ipotesi!$C$5-1)*60+0*12+1):INDEX(Motore_Advisory!$Y$5:$Y$544,((Ipotesi!$C$5-1)*60+0*12+1)+11)) -> 35048.126 | D16: =SUM(INDEX(Motore_Advisory!$Y$5:$Y$544,(Ipotesi!$C$5-1)*60+1*12+1):INDEX(Motore_Advisory!$Y$5:$Y$544,((Ipotesi!$C$5-1)*60+1*12+1)+11)) -> 42717.755 | E16: =SUM(INDEX(Motore_Advisory!$Y$5:$Y$544,(Ipotesi!$C$5-1)*60+2*12+1):INDEX(Motore_Advisory!$Y$5:$Y$544,((Ipotesi!$C$5-1)*60+2*12+1)+11)) -> 120631.81 | F16: =SUM(INDEX(Motore_Advisory!$Y$5:$Y$544,(Ipotesi!$C$5-1)*60+3*12+1):INDEX(Motore_Advisory!$Y$5:$Y$544,((Ipotesi!$C$5-1)*60+3*12+1)+11)) -> 235552 | G16: =SUM(INDEX(Motore_Advisory!$Y$5:$Y$544,(Ipotesi!$C$5-1)*60+4*12+1):INDEX(Motore_Advisory!$Y$5:$Y$544,((Ipotesi!$C$5-1)*60+4*12+1)+11)) -> 309635.37
