Workbook

Sheet Riepilogo
A1: Personale di casa – costo reale (pagamento in contanti, senza contratto)
A2: Inserire in blu/giallo nome, mansione, paga oraria e ore settimanali. Il resto è calcolato.
A4: Lavoratrice | B4: Mansione | C4: Paga oraria (€) | D4: Ore / settimana | E4: Costo settimanale (€) | F4: Costo medio mensile (€) | G4: Costo annuo (€) | H4: % sul totale
A5: Oshina | B5: Colf | C5: 11.5 | D5: 9 | E5: =C5*D5 -> 103.5 | F5: =E5*Parametri!$B$6/Parametri!$B$7 -> 448.5 | G5: =E5*Parametri!$B$6 -> 5382 | H5: =IF($G$8=0,0,G5/$G$8) -> 0.48027842
A6: Elisa | B6: Da specificare | C6: 12 | D6: 6 | E6: =C6*D6 -> 72 | F6: =E6*Parametri!$B$6/Parametri!$B$7 -> 312 | G6: =E6*Parametri!$B$6 -> 3744 | H6: =IF($G$8=0,0,G6/$G$8) -> 0.33410673
A7: Corina | B7: Da specificare | C7: 10 | D7: 4 | E7: =C7*D7 -> 40 | F7: =E7*Parametri!$B$6/Parametri!$B$7 -> 173.33333 | G7: =E7*Parametri!$B$6 -> 2080 | H7: =IF($G$8=0,0,G7/$G$8) -> 0.18561485
A8: TOTALE | C8: =IF(D8=0,0,E8/D8) -> 11.342105 | D8: =SUM(D5:D7) -> 19 | E8: =SUM(E5:E7) -> 215.5 | F8: =SUM(F5:F7) -> 933.83333 | G8: =SUM(G5:G7) -> 11206 | H8: =SUM(H5:H7) -> 1
A11: Indicatori
A12: Contanti da prelevare in un mese medio | B12: =F8 -> 933.83333
A13: Contanti in un mese con 5 settimane | B13: =E8*5 -> 1077.5
A14: Contanti in un mese con 4 settimane | B14: =E8*4 -> 862
A15: Ore totali di aiuto in casa all'anno | B15: =D8*Parametri!$B$6 -> 988
A16: Paga oraria media ponderata | B16: =C8 -> 11.342105
A19: Note
A20: 1. Paga oraria e ore settimanali indicati dall'utente. Mansioni di Elisa e Corina non specificate: modificarle in colonna B.
A21: 2. Mese medio = 52 settimane / 12 = 4,33 settimane. I mesi con 5 settimane costano di più: vedi foglio 'Registro contanti'.
A22: 3. Il foglio 'Confronto se regolare' mostra quanto costerebbe lo stesso aiuto con un contratto (contributi, 13ª, TFR, ferie pagate).

Sheet Parametri
A1: Parametri
A2: Celle blu su sfondo giallo = modificabili. Tutti gli altri fogli si ricalcolano da qui.
A4: Parametro | B4: Valore | C4: Nota
A5: Anno del registro | B5: 2027 | C5: Anno usato nel Registro contanti per contare le settimane di ogni mese
A6: Settimane pagate / anno | B6: 52 | C6: 52 = si paga ogni settimana. Se in ferie/assenze non si paga, ridurre (es. 48)
A7: Mesi / anno | B7: 12
A10: Parametri per il confronto con un rapporto regolare
A11: Parametro | B11: Valore | C11: Fonte / nota
A12: Settimane retribuite / anno (rapporto regolare) | B12: 52 | C12: Con contratto le ferie (26 gg/anno, CCNL lavoro domestico) sono pagate: 52 settimane
A13: Mensilità di tredicesima | B13: 1 | C13: CCNL lavoro domestico: 1 mensilità, a dicembre
A14: Divisore TFR | B14: 13.5 | C14: Art. 2120 c.c.: TFR annuo = retribuzione annua (13ª inclusa) / 13,5
A15: Cassa Colf - totale (€/ora) | B15: 0.06 | C15: Contributo assistenza contrattuale CCNL (0,04 datore + 0,02 lavoratore). Da verificare
A18: Contributi orari INPS lavoro domestico 2026 (con CUAF, tempo indeterminato, fino a 24 h/settimana)
A19: Fonte: INPS Circolare n. 9 del 03/02/2026 (come riportata da quifinanza.it, tutelaprevidenziale.it, edotto.com). Verificare sul sito INPS; si aggiorna ogni anno a gennaio/febbraio.
A20: Retribuzione oraria effettiva da (€) | B20: Contributo totale (€/h) | C20: di cui quota lavoratore (€/h) | D20: Fascia
A21: 0 | B21: 1.7 | C21: 0.43 | D21: Fino a 9,61 €
A22: 9.62 | B22: 1.92 | C22: 0.48 | D22: Da 9,62 a 11,70 €
A23: 11.71 | B23: 2.34 | C23: 0.59 | D23: Oltre 11,70 €
A24: Oltre 24 ore settimanali (qualsiasi paga) | B24: 1.24 | C24: 0.31 | D24: > 24 h/settimana
A25: La fascia si determina sulla paga oraria comprensiva del rateo di 13ª (paga × 13/12).

Sheet Registro contanti
A1: Registro pagamenti in contanti
A2: Ore previste = ore settimanali × lunedì del mese. Se le ore reali sono diverse scriverle in 'Ore effettive' (se vuoto si usano le previste). Segnare data e SI quando pagato.
A4: Mese | B4: N. mese | C4: Lavoratrice | D4: Paga oraria (€) | E4: Ore previste | F4: Ore effettive | G4: Importo (€) | H4: Data pagamento | I4: Pagato (SI/NO) | J4: Note
A5: Gennaio | B5: 1 | C5: =Riepilogo!$A$5 -> Oshina | D5: =Riepilogo!$C$5 -> 11.5 | E5: =Riepilogo!$D$5*SUMPRODUCT(--(WEEKDAY(DATE(Parametri!$B$5,B5,1)+ROW($A$1:$A$31)-1,2)=1),--(ROW($A$1:$A$31)<=DAY(DATE(Parametri!$B$5,B5+1,0)))) -> 36 | G5: =IF(F5="",E5,F5)*D5 -> 414
A6: Gennaio | B6: 1 | C6: =Riepilogo!$A$6 -> Elisa | D6: =Riepilogo!$C$6 -> 12 | E6: =Riepilogo!$D$6*SUMPRODUCT(--(WEEKDAY(DATE(Parametri!$B$5,B6,1)+ROW($A$1:$A$31)-1,2)=1),--(ROW($A$1:$A$31)<=DAY(DATE(Parametri!$B$5,B6+1,0)))) -> 24 | G6: =IF(F6="",E6,F6)*D6 -> 288
A7: Gennaio | B7: 1 | C7: =Riepilogo!$A$7 -> Corina | D7: =Riepilogo!$C$7 -> 10 | E7: =Riepilogo!$D$7*SUMPRODUCT(--(WEEKDAY(DATE(Parametri!$B$5,B7,1)+ROW($A$1:$A$31)-1,2)=1),--(ROW($A$1:$A$31)<=DAY(DATE(Parametri!$B$5,B7+1,0)))) -> 16 | G7: =IF(F7="",E7,F7)*D7 -> 160
A8: Febbraio | B8: 2 | C8: =Riepilogo!$A$5 -> Oshina | D8: =Riepilogo!$C$5 -> 11.5 | E8: =Riepilogo!$D$5*SUMPRODUCT(--(WEEKDAY(DATE(Parametri!$B$5,B8,1)+ROW($A$1:$A$31)-1,2)=1),--(ROW($A$1:$A$31)<=DAY(DATE(Parametri!$B$5,B8+1,0)))) -> 36 | G8: =IF(F8="",E8,F8)*D8 -> 414
A9: Febbraio | B9: 2 | C9: =Riepilogo!$A$6 -> Elisa | D9: =Riepilogo!$C$6 -> 12 | E9: =Riepilogo!$D$6*SUMPRODUCT(--(WEEKDAY(DATE(Parametri!$B$5,B9,1)+ROW($A$1:$A$31)-1,2)=1),--(ROW($A$1:$A$31)<=DAY(DATE(Parametri!$B$5,B9+1,0)))) -> 24 | G9: =IF(F9="",E9,F9)*D9 -> 288
A10: Febbraio | B10: 2 | C10: =Riepilogo!$A$7 -> Corina | D10: =Riepilogo!$C$7 -> 10 | E10: =Riepilogo!$D$7*SUMPRODUCT(--(WEEKDAY(DATE(Parametri!$B$5,B10,1)+ROW($A$1:$A$31)-1,2)=1),--(ROW($A$1:$A$31)<=DAY(DATE(Parametri!$B$5,B10+1,0)))) -> 16 | G10: =IF(F10="",E10,F10)*D10 -> 160
A11: Marzo | B11: 3 | C11: =Riepilogo!$A$5 -> Oshina | D11: =Riepilogo!$C$5 -> 11.5 | E11: =Riepilogo!$D$5*SUMPRODUCT(--(WEEKDAY(DATE(Parametri!$B$5,B11,1)+ROW($A$1:$A$31)-1,2)=1),--(ROW($A$1:$A$31)<=DAY(DATE(Parametri!$B$5,B11+1,0)))) -> 45 | G11: =IF(F11="",E11,F11)*D11 -> 517.5
A12: Marzo | B12: 3 | C12: =Riepilogo!$A$6 -> Elisa | D12: =Riepilogo!$C$6 -> 12 | E12: =Riepilogo!$D$6*SUMPRODUCT(--(WEEKDAY(DATE(Parametri!$B$5,B12,1)+ROW($A$1:$A$31)-1,2)=1),--(ROW($A$1:$A$31)<=DAY(DATE(Parametri!$B$5,B12+1,0)))) -> 30 | G12: =IF(F12="",E12,F12)*D12 -> 360
A13: Marzo | B13: 3 | C13: =Riepilogo!$A$7 -> Corina | D13: =Riepilogo!$C$7 -> 10 | E13: =Riepilogo!$D$7*SUMPRODUCT(--(WEEKDAY(DATE(Parametri!$B$5,B13,1)+ROW($A$1:$A$31)-1,2)=1),--(ROW($A$1:$A$31)<=DAY(DATE(Parametri!$B$5,B13+1,0)))) -> 20 | G13: =IF(F13="",E13,F13)*D13 -> 200
A14: Aprile | B14: 4 | C14: =Riepilogo!$A$5 -> Oshina | D14: =Riepilogo!$C$5 -> 11.5 | E14: =Riepilogo!$D$5*SUMPRODUCT(--(WEEKDAY(DATE(Parametri!$B$5,B14,1)+ROW($A$1:$A$31)-1,2)=1),--(ROW($A$1:$A$31)<=DAY(DATE(Parametri!$B$5,B14+1,0)))) -> 36 | G14: =IF(F14="",E14,F14)*D14 -> 414
A15: Aprile | B15: 4 | C15: =Riepilogo!$A$6 -> Elisa | D15: =Riepilogo!$C$6 -> 12 | E15: =Riepilogo!$D$6*SUMPRODUCT(--(WEEKDAY(DATE(Parametri!$B$5,B15,1)+ROW($A$1:$A$31)-1,2)=1),--(ROW($A$1:$A$31)<=DAY(DATE(Parametri!$B$5,B15+1,0)))) -> 24 | G15: =IF(F15="",E15,F15)*D15 -> 288
A16: Aprile | B16: 4 | C16: =Riepilogo!$A$7 -> Corina | D16: =Riepilogo!$C$7 -> 10 | E16: =Riepilogo!$D$7*SUMPRODUCT(--(WEEKDAY(DATE(Parametri!$B$5,B16,1)+ROW($A$1:$A$31)-1,2)=1),--(ROW($A$1:$A$31)<=DAY(DATE(Parametri!$B$5,B16+1,0)))) -> 16 | G16: =IF(F16="",E16,F16)*D16 -> 160
A17: Maggio | B17: 5 | C17: =Riepilogo!$A$5 -> Oshina | D17: =Riepilogo!$C$5 -> 11.5 | E17: =Riepilogo!$D$5*SUMPRODUCT(--(WEEKDAY(DATE(Parametri!$B$5,B17,1)+ROW($A$1:$A$31)-1,2)=1),--(ROW($A$1:$A$31)<=DAY(DATE(Parametri!$B$5,B17+1,0)))) -> 45 | G17: =IF(F17="",E17,F17)*D17 -> 517.5
A18: Maggio | B18: 5 | C18: =Riepilogo!$A$6 -> Elisa | D18: =Riepilogo!$C$6 -> 12 | E18: =Riepilogo!$D$6*SUMPRODUCT(--(WEEKDAY(DATE(Parametri!$B$5,B18,1)+ROW($A$1:$A$31)-1,2)=1),--(ROW($A$1:$A$31)<=DAY(DATE(Parametri!$B$5,B18+1,0)))) -> 30 | G18: =IF(F18="",E18,F18)*D18 -> 360
A19: Maggio | B19: 5 | C19: =Riepilogo!$A$7 -> Corina | D19: =Riepilogo!$C$7 -> 10 | E19: =Riepilogo!$D$7*SUMPRODUCT(--(WEEKDAY(DATE(Parametri!$B$5,B19,1)+ROW($A$1:$A$31)-1,2)=1),--(ROW($A$1:$A$31)<=DAY(DATE(Parametri!$B$5,B19+1,0)))) -> 20 | G19: =IF(F19="",E19,F19)*D19 -> 200
A20: Giugno | B20: 6 | C20: =Riepilogo!$A$5 -> Oshina | D20: =Riepilogo!$C$5 -> 11.5 | E20: =Riepilogo!$D$5*SUMPRODUCT(--(WEEKDAY(DATE(Parametri!$B$5,B20,1)+ROW($A$1:$A$31)-1,2)=1),--(ROW($A$1:$A$31)<=DAY(DATE(Parametri!$B$5,B20+1,0)))) -> 36 | G20: =IF(F20="",E20,F20)*D20 -> 414
A21: Giugno | B21: 6 | C21: =Riepilogo!$A$6 -> Elisa | D21: =Riepilogo!$C$6 -> 12 | E21: =Riepilogo!$D$6*SUMPRODUCT(--(WEEKDAY(DATE(Parametri!$B$5,B21,1)+ROW($A$1:$A$31)-1,2)=1),--(ROW($A$1:$A$31)<=DAY(DATE(Parametri!$B$5,B21+1,0)))) -> 24 | G21: =IF(F21="",E21,F21)*D21 -> 288
A22: Giugno | B22: 6 | C22: =Riepilogo!$A$7 -> Corina | D22: =Riepilogo!$C$7 -> 10 | E22: =Riepilogo!$D$7*SUMPRODUCT(--(WEEKDAY(DATE(Parametri!$B$5,B22,1)+ROW($A$1:$A$31)-1,2)=1),--(ROW($A$1:$A$31)<=DAY(DATE(Parametri!$B$5,B22+1,0)))) -> 16 | G22: =IF(F22="",E22,F22)*D22 -> 160
A23: Luglio | B23: 7 | C23: =Riepilogo!$A$5 -> Oshina | D23: =Riepilogo!$C$5 -> 11.5 | E23: =Riepilogo!$D$5*SUMPRODUCT(--(WEEKDAY(DATE(Parametri!$B$5,B23,1)+ROW($A$1:$A$31)-1,2)=1),--(ROW($A$1:$A$31)<=DAY(DATE(Parametri!$B$5,B23+1,0)))) -> 36 | G23: =IF(F23="",E23,F23)*D23 -> 414
A24: Luglio | B24: 7 | C24: =Riepilogo!$A$6 -> Elisa | D24: =Riepilogo!$C$6 -> 12 | E24: =Riepilogo!$D$6*SUMPRODUCT(--(WEEKDAY(DATE(Parametri!$B$5,B24,1)+ROW($A$1:$A$31)-1,2)=1),--(ROW($A$1:$A$31)<=DAY(DATE(Parametri!$B$5,B24+1,0)))) -> 24 | G24: =IF(F24="",E24,F24)*D24 -> 288
A25: Luglio | B25: 7 | C25: =Riepilogo!$A$7 -> Corina | D25: =Riepilogo!$C$7 -> 10 | E25: =Riepilogo!$D$7*SUMPRODUCT(--(WEEKDAY(DATE(Parametri!$B$5,B25,1)+ROW($A$1:$A$31)-1,2)=1),--(ROW($A$1:$A$31)<=DAY(DATE(Parametri!$B$5,B25+1,0)))) -> 16 | G25: =IF(F25="",E25,F25)*D25 -> 160
A26: Agosto | B26: 8 | C26: =Riepilogo!$A$5 -> Oshina | D26: =Riepilogo!$C$5 -> 11.5 | E26: =Riepilogo!$D$5*SUMPRODUCT(--(WEEKDAY(DATE(Parametri!$B$5,B26,1)+ROW($A$1:$A$31)-1,2)=1),--(ROW($A$1:$A$31)<=DAY(DATE(Parametri!$B$5,B26+1,0)))) -> 45 | G26: =IF(F26="",E26,F26)*D26 -> 517.5
A27: Agosto | B27: 8 | C27: =Riepilogo!$A$6 -> Elisa | D27: =Riepilogo!$C$6 -> 12 | E27: =Riepilogo!$D$6*SUMPRODUCT(--(WEEKDAY(DATE(Parametri!$B$5,B27,1)+ROW($A$1:$A$31)-1,2)=1),--(ROW($A$1:$A$31)<=DAY(DATE(Parametri!$B$5,B27+1,0)))) -> 30 | G27: =IF(F27="",E27,F27)*D27 -> 360
A28: Agosto | B28: 8 | C28: =Riepilogo!$A$7 -> Corina | D28: =Riepilogo!$C$7 -> 10 | E28: =Riepilogo!$D$7*SUMPRODUCT(--(WEEKDAY(DATE(Parametri!$B$5,B28,1)+ROW($A$1:$A$31)-1,2)=1),--(ROW($A$1:$A$31)<=DAY(DATE(Parametri!$B$5,B28+1,0)))) -> 20 | G28: =IF(F28="",E28,F28)*D28 -> 200
A29: Settembre | B29: 9 | C29: =Riepilogo!$A$5 -> Oshina | D29: =Riepilogo!$C$5 -> 11.5 | E29: =Riepilogo!$D$5*SUMPRODUCT(--(WEEKDAY(DATE(Parametri!$B$5,B29,1)+ROW($A$1:$A$31)-1,2)=1),--(ROW($A$1:$A$31)<=DAY(DATE(Parametri!$B$5,B29+1,0)))) -> 36 | G29: =IF(F29="",E29,F29)*D29 -> 414
A30: Settembre | B30: 9 | C30: =Riepilogo!$A$6 -> Elisa | D30: =Riepilogo!$C$6 -> 12 | E30: =Riepilogo!$D$6*SUMPRODUCT(--(WEEKDAY(DATE(Parametri!$B$5,B30,1)+ROW($A$1:$A$31)-1,2)=1),--(ROW($A$1:$A$31)<=DAY(DATE(Parametri!$B$5,B30+1,0)))) -> 24 | G30: =IF(F30="",E30,F30)*D30 -> 288
A31: Settembre | B31: 9 | C31: =Riepilogo!$A$7 -> Corina | D31: =Riepilogo!$C$7 -> 10 | E31: =Riepilogo!$D$7*SUMPRODUCT(--(WEEKDAY(DATE(Parametri!$B$5,B31,1)+ROW($A$1:$A$31)-1,2)=1),--(ROW($A$1:$A$31)<=DAY(DATE(Parametri!$B$5,B31+1,0)))) -> 16 | G31: =IF(F31="",E31,F31)*D31 -> 160
A32: Ottobre | B32: 10 | C32: =Riepilogo!$A$5 -> Oshina | D32: =Riepilogo!$C$5 -> 11.5 | E32: =Riepilogo!$D$5*SUMPRODUCT(--(WEEKDAY(DATE(Parametri!$B$5,B32,1)+ROW($A$1:$A$31)-1,2)=1),--(ROW($A$1:$A$31)<=DAY(DATE(Parametri!$B$5,B32+1,0)))) -> 36 | G32: =IF(F32="",E32,F32)*D32 -> 414
A33: Ottobre | B33: 10 | C33: =Riepilogo!$A$6 -> Elisa | D33: =Riepilogo!$C$6 -> 12 | E33: =Riepilogo!$D$6*SUMPRODUCT(--(WEEKDAY(DATE(Parametri!$B$5,B33,1)+ROW($A$1:$A$31)-1,2)=1),--(ROW($A$1:$A$31)<=DAY(DATE(Parametri!$B$5,B33+1,0)))) -> 24 | G33: =IF(F33="",E33,F33)*D33 -> 288
A34: Ottobre | B34: 10 | C34: =Riepilogo!$A$7 -> Corina | D34: =Riepilogo!$C$7 -> 10 | E34: =Riepilogo!$D$7*SUMPRODUCT(--(WEEKDAY(DATE(Parametri!$B$5,B34,1)+ROW($A$1:$A$31)-1,2)=1),--(ROW($A$1:$A$31)<=DAY(DATE(Parametri!$B$5,B34+1,0)))) -> 16 | G34: =IF(F34="",E34,F34)*D34 -> 160
A35: Novembre | B35: 11 | C35: =Riepilogo!$A$5 -> Oshina | D35: =Riepilogo!$C$5 -> 11.5 | E35: =Riepilogo!$D$5*SUMPRODUCT(--(WEEKDAY(DATE(Parametri!$B$5,B35,1)+ROW($A$1:$A$31)-1,2)=1),--(ROW($A$1:$A$31)<=DAY(DATE(Parametri!$B$5,B35+1,0)))) -> 45 | G35: =IF(F35="",E35,F35)*D35 -> 517.5
A36: Novembre | B36: 11 | C36: =Riepilogo!$A$6 -> Elisa | D36: =Riepilogo!$C$6 -> 12 | E36: =Riepilogo!$D$6*SUMPRODUCT(--(WEEKDAY(DATE(Parametri!$B$5,B36,1)+ROW($A$1:$A$31)-1,2)=1),--(ROW($A$1:$A$31)<=DAY(DATE(Parametri!$B$5,B36+1,0)))) -> 30 | G36: =IF(F36="",E36,F36)*D36 -> 360
A37: Novembre | B37: 11 | C37: =Riepilogo!$A$7 -> Corina | D37: =Riepilogo!$C$7 -> 10 | E37: =Riepilogo!$D$7*SUMPRODUCT(--(WEEKDAY(DATE(Parametri!$B$5,B37,1)+ROW($A$1:$A$31)-1,2)=1),--(ROW($A$1:$A$31)<=DAY(DATE(Parametri!$B$5,B37+1,0)))) -> 20 | G37: =IF(F37="",E37,F37)*D37 -> 200
A38: Dicembre | B38: 12 | C38: =Riepilogo!$A$5 -> Oshina | D38: =Riepilogo!$C$5 -> 11.5 | E38: =Riepilogo!$D$5*SUMPRODUCT(--(WEEKDAY(DATE(Parametri!$B$5,B38,1)+ROW($A$1:$A$31)-1,2)=1),--(ROW($A$1:$A$31)<=DAY(DATE(Parametri!$B$5,B38+1,0)))) -> 36 | G38: =IF(F38="",E38,F38)*D38 -> 414
A39: Dicembre | B39: 12 | C39: =Riepilogo!$A$6 -> Elisa | D39: =Riepilogo!$C$6 -> 12 | E39: =Riepilogo!$D$6*SUMPRODUCT(--(WEEKDAY(DATE(Parametri!$B$5,B39,1)+ROW($A$1:$A$31)-1,2)=1),--(ROW($A$1:$A$31)<=DAY(DATE(Parametri!$B$5,B39+1,0)))) -> 24 | G39: =IF(F39="",E39,F39)*D39 -> 288
A40: Dicembre | B40: 12 | C40: =Riepilogo!$A$7 -> Corina | D40: =Riepilogo!$C$7 -> 10 | E40: =Riepilogo!$D$7*SUMPRODUCT(--(WEEKDAY(DATE(Parametri!$B$5,B40,1)+ROW($A$1:$A$31)-1,2)=1),--(ROW($A$1:$A$31)<=DAY(DATE(Parametri!$B$5,B40+1,0)))) -> 16 | G40: =IF(F40="",E40,F40)*D40 -> 160
A41: TOTALE ANNO | E41: =SUM(E5:E40) -> 988 | F41: =SUM(F5:F40) -> 0 | G41: =SUM(G5:G40) -> 11206
...

Sheet Confronto se regolare
A1: Quanto costerebbe lo stesso aiuto con un contratto regolare
A2: Stesse paghe orarie e ore del Riepilogo. Parametri INPS 2026 nel foglio Parametri. La famiglia paga anche la quota INPS della lavoratrice (paga concordata netta).
A4: Lavoratrice | B4: Paghe 52 settimane, ferie incluse (€) | C4: Tredicesima (€) | D4: Paga oraria incl. 13ª (€) | E4: Contributo INPS orario (€) | F4: INPS annuo (€) | G4: Cassa Colf annua (€) | H4: TFR annuo (€) | I4: COSTO REGOLARE ANNUO (€) | J4: Costo attuale in contanti (€) | K4: Differenza annua (€) | L4: Differenza mensile (€) | M4: Rincaro %
A5: =Riepilogo!A5 -> Oshina | B5: =Riepilogo!E5*Parametri!$B$12 -> 5382 | C5: =B5/Parametri!$B$7*Parametri!$B$13 -> 448.5 | D5: =Riepilogo!C5*(Parametri!$B$7+Parametri!$B$13)/Parametri!$B$7 -> 12.458333 | E5: =IF(Riepilogo!D5>24,Parametri!$B$24,INDEX(Parametri!$B$21:$B$23,MATCH(D5,Parametri!$A$21:$A$23,1))) -> 2.34 | F5: =E5*Riepilogo!D5*Parametri!$B$12 -> 1095.12 | G5: =Parametri!$B$15*Riepilogo!D5*Parametri!$B$12 -> 28.08 | H5: =(B5+C5)/Parametri!$B$14 -> 431.88889 | I5: =B5+C5+F5+G5+H5 -> 7385.5889 | J5: =Riepilogo!G5 -> 5382 | K5: =I5-J5 -> 2003.5889 | L5: =K5/Parametri!$B$7 -> 166.96574 | M5: =IF(J5=0,0,K5/J5) -> 0.3722759
A6: =Riepilogo!A6 -> Elisa | B6: =Riepilogo!E6*Parametri!$B$12 -> 3744 | C6: =B6/Parametri!$B$7*Parametri!$B$13 -> 312 | D6: =Riepilogo!C6*(Parametri!$B$7+Parametri!$B$13)/Parametri!$B$7 -> 13 | E6: =IF(Riepilogo!D6>24,Parametri!$B$24,INDEX(Parametri!$B$21:$B$23,MATCH(D6,Parametri!$A$21:$A$23,1))) -> 2.34 | F6: =E6*Riepilogo!D6*Parametri!$B$12 -> 730.08 | G6: =Parametri!$B$15*Riepilogo!D6*Parametri!$B$12 -> 18.72 | H6: =(B6+C6)/Parametri!$B$14 -> 300.44444 | I6: =B6+C6+F6+G6+H6 -> 5105.2444 | J6: =Riepilogo!G6 -> 3744 | K6: =I6-J6 -> 1361.2444 | L6: =K6/Parametri!$B$7 -> 113.43704 | M6: =IF(J6=0,0,K6/J6) -> 0.36358025
A7: =Riepilogo!A7 -> Corina | B7: =Riepilogo!E7*Parametri!$B$12 -> 2080 | C7: =B7/Parametri!$B$7*Parametri!$B$13 -> 173.33333 | D7: =Riepilogo!C7*(Parametri!$B$7+Parametri!$B$13)/Parametri!$B$7 -> 10.833333 | E7: =IF(Riepilogo!D7>24,Parametri!$B$24,INDEX(Parametri!$B$21:$B$23,MATCH(D7,Parametri!$A$21:$A$23,1))) -> 1.92 | F7: =E7*Riepilogo!D7*Parametri!$B$12 -> 399.36 | G7: =Parametri!$B$15*Riepilogo!D7*Parametri!$B$12 -> 12.48 | H7: =(B7+C7)/Parametri!$B$14 -> 166.91358 | I7: =B7+C7+F7+G7+H7 -> 2832.0869 | J7: =Riepilogo!G7 -> 2080 | K7: =I7-J7 -> 752.08691 | L7: =K7/Parametri!$B$7 -> 62.673909 | M7: =IF(J7=0,0,K7/J7) -> 0.36158025
A8: TOTALE | B8: =SUM(B5:B7) -> 11206 | C8: =SUM(C5:C7) -> 933.83333 | F8: =SUM(F5:F7) -> 2224.56 | G8: =SUM(G5:G7) -> 59.28 | H8: =SUM(H5:H7) -> 899.24691 | I8: =SUM(I5:I7) -> 15322.92 | J8: =SUM(J5:J7) -> 11206 | K8: =SUM(K5:K7) -> 4116.9202 | L8: =SUM(L5:L7) -> 343.07669 | M8: =IF(J8=0,0,K8/J8) -> 0.36738535
A11: Se si regolarizza: cosa cambia in pratica
A12: Contributi INPS + Cassa Colf per trimestre (pagoPA, scad. 10/4, 10/7, 10/10, 10/1) | B12: =(F8+G8)/4 -> 570.96
A13: TFR da accantonare ogni mese | B13: =H8/Parametri!$B$7 -> 74.937243
A14: Tredicesime da pagare a dicembre | B14: =C8 -> 933.83333
A15: Contributi deducibili dal reddito (quota datore, max 1.549,37 €) – stima | B15: =MIN(1549.37,(E5-INDEX(Parametri!$C$21:$C$23,MATCH(D5,Parametri!$A$21:$A$23,1)))*Riepilogo!D5*Parametri!$B$12+(E6-INDEX(Parametri!$C$21:$C$23,MATCH(D6,Parametri!$A$21:$A$23,1)))*Riepilogo!D6*Parametri!$B$12+(E7-INDEX(Parametri!$C$21:$C$23,MATCH(D7,Parametri!$A$21:$A$23,1)))*Riepilogo!D7*Parametri!$B$12) -> 1549.37 | C15: Art. 10 c.2 TUIR: deducibili i soli contributi a carico del datore. Il risparmio d'imposta dipende dall'aliquota IRPEF.
A18: Rischi del rapporto senza contratto (informativo)
A19: • La lavoratrice può chiedere, anche anni dopo la fine del rapporto, 13ª, ferie, TFR e differenze: in pratica i valori della tabella sopra per ogni anno lavorato.
A20: • INPS può recuperare i contributi non versati degli ultimi 5 anni, con sanzioni civili e interessi.
A21: • Senza assicurazione INAIL (inclusa nei contributi), un infortunio in casa resta a carico della famiglia.
A22: • Il pagamento in contanti per il lavoro domestico è comunque ammesso (anche con contratto), sotto la soglia di 5.000 €.
A23: • Per una valutazione sulla propria situazione: patronato, CAF o associazioni datori di lavoro domestico (es. Assindatcolf, Domina).
